Workbook

Sheet Kraken
A1: ü c | B1: Date sent to acctnt | C1: Entry Date | D1: XRP address | E1: Desti- nation tag | F1: Tran- action ID | G1: Description | H1: Type | I1: Amount | J1: Fee | K1: Balance | L1: Asset | M1: Amount | N1: Fee | O1: Balance | P1: Asset | Q1: Aleksey Trofimov GBP | S1: Evgeniy Ulyukin GBP | U1: Category | V1: # | W1: Payslip date | X1: Comment
A2: ü | C2: 44824 | G2: Transfer from Santander Business | H2: DEPOSIT | I2: 100.05 | K2: =+I2-J2 -> 100.05 | L2: GBP | O2: =+M2-N2 -> 0 | X2: Deposit via payment processor Payward Ltd
A3: ü | C3: 44824 | G3: Transfer from Santander Business | H3: DEPOSIT | I3: 3300 | K3: =+K2+I3-J3 -> 3400.05 | L3: GBP | O3: =+O2+M3-N3 -> 0 | X3: Deposit via payment processor Payward Ltd
A4: ü | C4: 44825 | G4: Convert GBP to XRP | H4: TRADE | I4: -34.797 | J4: 0.0905 | K4: =+K3+I4-J4 -> 3365.1625 | L4: GBP | M4: 100 | N4: 0 | O4: =+O3+M4-N4 -> 100 | P4: XRP | R4: x | V4: 5 | W4: 43707
A5: ü | C5: 44825 | D5: rEb8TK3gBgk5auZkwc6sHnwrGVJH8DuaLh | E5: 547786843 | F5: https://xrpscan.com/tx/9FBD5122F4A1ABF20B0705C3447962E6F13C24D7B045494CD8DB71FA7DAD2B21 | G5: Aleksey Trofimov | H5: WITHDRAW | K5: =+K4+I5-J5 -> 3365.1625 | M5: -99.98 | N5: 0.02 | O5: =+O4+M5-N5 -> -3.9794557e-15 | P5: XRP | R5: x | V5: 5 | W5: 43707
A6: ü | C6: 44825 | G6: Convert GBP to XRP | H6: TRADE | I6: -1716.3447 | J6: 4.4625 | K6: =+K5+I6-J6 -> 1644.3553 | L6: GBP | M6: 4900 | N6: 0 | O6: =+O5+M6-N6 -> 4900 | P6: XRP | R6: x
A7: ü | C7: 44825 | D7: rEb8TK3gBgk5auZkwc6sHnwrGVJH8DuaLh | E7: 547786843 | F7: https://xrpscan.com/tx/9ED991B6FD966C3739300B4009C5CBCC786DF95B3E65C161ED78ABECD8BE2317 | G7: Aleksey Trofimov | H7: WITHDRAW | K7: =+K6+I7-J7 -> 1644.3553 | M7: -4899.98 | N7: 0.02 | O7: =+O6+M7-N7 -> 4.3655704e-13 | P7: XRP | R7: x
A8: ü | C8: 44825 | G8: Convert GBP to XRP | H8: TRADE | I8: -1585.7104 | J8: 4.1228 | K8: =+K7+I8-J8 -> 54.5221 | L8: GBP | M8: 4500 | N8: 0 | O8: =+O7+M8-N8 -> 4500 | P8: XRP | R8: x
A9: ü | B9: 44844 | C9: 44825 | D9: rEb8TK3gBgk5auZkwc6sHnwrGVJH8DuaLh | E9: 547786843 | F9: https://xrpscan.com/tx/5A244C410691D52736EE42C6C070B03D25604A34EC222046B9D30E308913F5D7 | G9: Aleksey Trofimov | H9: WITHDRAW | K9: =+K8+I9-J9 -> 54.5221 | M9: -4499.98 | N9: 0.02 | O9: =+O8+M9-N9 -> 4.3655704e-13 | P9: XRP | Q9: =-(I4+I6+I8) -> 3336.8521 | R9: x | U9: Consulting fee - Aleksey Trofimov
A10: ü | C10: 44833 | G10: Transfer from Santander Business | H10: DEPOSIT | I10: 100 | K10: =+K9+I10-J10 -> 154.5221 | L10: GBP | O10: =+O9+M10-N10 -> 4.3655704e-13 | X10: Deposit via payment processor Payward Ltd
A11: ü | C11: 44833 | G11: Convert GBP to XRP | H11: TRADE | I11: -152.3258 | J11: 0.3961 | K11: =+K10+I11-J11 -> 1.8002 | L11: GBP | M11: 375 | N11: 0 | O11: =+O10+M11-N11 -> 375 | P11: XRP | T11: x
A12: ü | B12: 44844 | C12: 44833 | D12: rEb8TK3gBgk5auZkwc6sHnwrGVJH8DuaLh | E12: 442734179 | F12: https://xrpscan.com/tx/437FA042365ECE9CD8DD068C413D4FBFCB4B91DA8B64A0010B9FB501FD655CBC | G12: Evgeniy Ulyukin | H12: WITHDRAW | K12: =+K11+I12-J12 -> 1.8002 | M12: -374.98 | N12: 0.02 | O12: =+O11+M12-N12 -> 4.3655704e-13 | P12: XRP | R12: x | S12: =-I11 -> 152.3258 | T12: x | U12: Consulting fee - Evgeniy Ulyukin
A13: ü | C13: 44841 | G13: Transfer from Santander Business | H13: DEPOSIT | I13: 3300 | K13: =+K12+I13-J13 -> 3301.8002 | L13: GBP | O13: =+O12+M13-N13 -> 4.3655704e-13 | X13: Deposit via payment processor Payward Ltd
A14: ü | C14: 44841 | G14: Convert GBP to XRP | H14: TRADE | I14: -1808.0891 | J14: 4.701 | K14: =+K13+I14-J14 -> 1489.0101 | L14: GBP | M14: 4000.02 | N14: 0 | O14: =+O13+M14-N14 -> 4000.02 | P14: XRP | R14: x
A15: ü | C15: 44841 | G15: Convert GBP to XRP | H15: TRADE | I15: -1486.0731 | J15: 0.351 | K15: =+K14+I15-J15 -> 2.586 | L15: GBP | M15: 3280.02 | N15: 7.7541988 | O15: =+O14+M15-N15 -> 7272.2858 | P15: XRP | R15: x
A16: ü | B16: 44844 | C16: 44841 | D16: rEb8TK3gBgk5auZkwc6sHnwrGVJH8DuaLh | E16: 547786843 | F16: https://xrpscan.com/tx/02EC21E0D411DE5EEE4A006C3CC2D95DE95B19E031D9C05D9AB49513036904F6 | G16: Aleksey Trofimov | H16: WITHDRAW | K16: =+K15+I16-J16 -> 2.586 | M16: -7270.02 | N16: 0.02 | O16: =+O15+M16-N16 -> 2.2458012 | P16: XRP | Q16: =-(I14+I15) -> 3294.1622 | R16: x | U16: Consulting fee - Aleksey Trofimov
A17: ü | C17: 44842 | G17: Transfer from Santander Business | H17: DEPOSIT | I17: 525 | K17: =+K16+I17-J17 -> 527.586 | L17: GBP | O17: =+O16+M17-N17 -> 2.2458012 | X17: Deposit via payment processor Payward Ltd
A18: ü | C18: 44842 | G18: Convert GBP to XRP | H18: TRADE | I18: -520.6519 | J18: 1.3537 | K18: =+K17+I18-J18 -> 5.5804 | L18: GBP | M18: 1110.02 | N18: 0 | O18: =+O17+M18-N18 -> 1112.2658 | P18: XRP | T18: x
A19: ü | B19: 44844 | C19: 44842 | D19: rEb8TK3gBgk5auZkwc6sHnwrGVJH8DuaLh | E19: 442734179 | F19: https://xrpscan.com/tx/F25CE3B619F0778F769EFF5B5752B15F4375A349D504DD38D4313F5D97868E51 | G19: Evgeniy Ulyukin | H19: WITHDRAW | K19: =+K18+I19-J19 -> 5.5804 | M19: -1110 | N19: 0.02 | O19: =+O18+M19-N19 -> 2.2458012 | P19: XRP | R19: x | S19: =-I18 -> 520.6519 | T19: x | U19: Consulting fee - Evgeniy Ulyukin
A20: ü | B20: 44844 | C20: 44842 | G20: Total Kraken fees for the month | J20: =SUM(J4:J19) -> 15.4776 | N20: =SUM(N4:N19) -> 7.8741988 | U20: Bank charges
A21: ü | C21: 44846 | G21: Transfer from Santander Business | H21: DEPOSIT | I21: 2205 | K21: =+K19+I21-J21 -> 2210.5804 | L21: GBP | O21: =+O19+M21-N21 -> 2.2458012 | X21: Deposit via payment processor Payward Ltd
A22: ü | C22: 44846 | G22: Convert GBP to XRP | H22: TRADE | I22: -2206.0574 | J22: 3.8092 | K22: =+K21+I22-J22 -> 0.7138 | L22: GBP | M22: 5000.02 | N22: 4.3675806 | O22: =+O21+M22-N22 -> 4997.8982 | P22: XRP | R22: x
A23: ü | B23: 44844 | C23: 44846 | D23: rEb8TK3gBgk5auZkwc6sHnwrGVJH8DuaLh | E23: 547786843 | F23: https://xrpscan.com/tx/2194D82FB4E82F6B64F0232B2B78FADB9DC1A17FB95CC8F9DC91514C6D99EBF4 | G23: Aleksey Trofimov | H23: WITHDRAW | K23: =+K22+I23-J23 -> 0.7138 | M23: -4995 | N23: 0.02 | O23: =+O22+M23-N23 -> 2.8782206 | P23: XRP | Q23: =-(I22) -> 2206.0574 | R23: x | U23: Consulting fee - Aleksey Trofimov
A24: ü | C24: 44855 | G24: Transfer from Santander Business | H24: DEPOSIT | I24: 100 | K24: =+K23+I24-J24 -> 100.7138 | L24: GBP | O24: =+O23+M24-N24 -> 2.8782206 | X24: Deposit via payment processor Payward Ltd
A25: ü | C25: 44855 | G25: Convert GBP to XRP | H25: TRADE | I25: -99.981 | J25: 0.26 | K25: =+K24+I25-J25 -> 0.4728 | L25: GBP | M25: 252 | N25: 0 | O25: =+O24+M25-N25 -> 254.87822 | P25: XRP | T25: x
A26: ü | B26: 44844 | C26: 44855 | D26: rEb8TK3gBgk5auZkwc6sHnwrGVJH8DuaLh | E26: 442734179 | F26: https://xrpscan.com/tx/3123170F050322C06D94A1C32D2CD56DFDAD23EC6450162C70CDEA1B55B3694E | G26: Evgeniy Ulyukin | H26: WITHDRAW | K26: =+K25+I26-J26 -> 0.4728 | M26: -250 | N26: 0.02 | O26: =+O25+M26-N26 -> 4.8582206 | P26: XRP | R26: x | S26: =-I25 -> 99.981 | T26: x | U26: Consulting fee - Evgeniy Ulyukin
A27: ü | C27: 44872 | G27: Transfer from Santander Business | H27: DEPOSIT | I27: 5000 | K27: =+K26+I27-J27 -> 5000.4728 | L27: GBP | O27: =+O26+M27-N27 -> 4.8582206 | X27: Deposit via payment processor Payward Ltd
A28: ü | C28: 44872 | G28: Convert GBP to XRP | H28: TRADE | I28: -5000.4728 | J28: 0 | K28: =+K27+I28-J28 -> 9.094947e-13 | L28: GBP | M28: 12112.744 | N28: 31.493136 | O28: =+O27+M28-N28 -> 12086.109 | P28: XRP | R28: x
A29: ü | B29: 44888 | C29: 44872 | D29: rEb8TK3gBgk5auZkwc6sHnwrGVJH8DuaLh | E29: 547786843 | F29: https://xrpscan.com/tx/5AB9C1C3052B58C5870398B4A7EB68738C3EBBED79AE1A75722E9BE4A235D8A2 | G29: Aleksey Trofimov | H29: WITHDRAW | K29: =+K28+I29-J29 -> 9.094947e-13 | M29: -12050 | N29: 0.02 | O29: =+O28+M29-N29 -> 36.089443 | P29: XRP | Q29: =-(I28) -> 5000.4728 | R29: x | U29: Consulting fee - Aleksey Trofimov
A30: ü | C30: 44872 | G30: Transfer from Santander Business | H30: DEPOSIT | I30: 500 | K30: =+K29+I30-J30 -> 500 | L30: GBP | O30: =+O29+M30-N30 -> 36.089443 | X30: Deposit via payment processor Payward Ltd
A31: ü | C31: 44872 | G31: Convert GBP to XRP | H31: TRADE | I31: -498.4837 | J31: 1.2961 | K31: =+K30+I31-J31 -> 0.2202 | L31: GBP | M31: 1210 | N31: 0 | O31: =+O30+M31-N31 -> 1246.0894 | P31: XRP | R31: x
A32: ü | B32: 44888 | C32: 44872 | D32: rEb8TK3gBgk5auZkwc6sHnwrGVJH8DuaLh | E32: 442734179 | F32: https://xrpscan.com/tx/B5E50E80B9A6016B1B2BF2150C79149F511227851CDB9E974A8F6030CDBC0A74 | G32: Evgeniy Ulyukin | H32: WITHDRAW | K32: =+K31+I32-J32 -> 0.2202 | M32: -1245 | N32: 0.02 | O32: =+O31+M32-N32 -> 1.0694428 | P32: XRP | R32: x | S32: =-(I31) -> 498.4837 | U32: Consulting fee - Evgeniy Ulyukin
A33: ü | B33: 44888 | C33: 44888 | G33: Total Kraken fees for the month | J33: =SUM(J22:J32) -> 5.3653 | L33: GBP | N33: =SUM(N22:N32) -> 35.940716 | P33: XRP | U33: Bank charges
A34: ü | B34: 45012 | C34: 44901 | G34: Transfer from Santander Business | H34: DEPOSIT | I34: 4765 | K34: =+K32+I34-J34 -> 4765.2202 | L34: GBP | O34: =+O33+M34-N34 -> 0 | X34: Deposit via payment processor Payward Ltd
A35: ü | B35: 45012 | C35: 44901 | G35: Convert GBP to XRP | H35: TRADE | I35: -4750.2938 | J35: 0 | K35: =+K34+I35-J35 -> 14.9264 | L35: GBP | M35: 15065 | N35: 0 | O35: =+O32+M35-N35 -> 15066.069 | P35: XRP | R35: x
A36: ü | B36: 45012 | C36: 44901 | D36: rEb8TK3gBgk5auZkwc6sHnwrGVJH8DuaLh | E36: 442734179 | F36: TBA | G36: Evgeniy Ulyukin | H36: WITHDRAW | K36: =+K35+I36-J36 -> 14.9264 | M36: -2060 | N36: 0.02 | O36: =+O35+M36-N36 -> 13006.049 | P36: XRP | R36: x | S36: =-M36/(M36+M37)*I35 -> 649.77458 | U36: Consulting fee - Evgeniy Ulyukin
A37: ü | B37: 45012 | C37: 44901 | D37: rEb8TK3gBgk5auZkwc6sHnwrGVJH8DuaLh | E37: 547786843 | F37: TBA | G37: Aleksey Trofimov | H37: WITHDRAW | K37: =+K36+I37-J37 -> 14.9264 | M37: -13000 | N37: 0.02 | O37: =+O36+M37-N37 -> 6.0294428 | P37: XRP | Q37: =-M37/(M36+M37)*I35 -> 4100.5192 | R37: x | U37: Consulting fee - Aleksey Trofimov
A38: ü | B38: 45012 | C38: 44916 | G38: Transfer from Santander Business | H38: DEPOSIT | I38: 350 | K38: =+K37+I38-J38 -> 364.9264 | L38: GBP | O38: =+O37+M38-N38 -> 6.0294428 | X38: Deposit via payment processor Payward Ltd
A39: ü | B39: 45012 | C39: 44916 | G39: Convert GBP to XRP | H39: TRADE | I39: -361.1116 | J39: 0 | K39: =+K38+I39-J39 -> 3.8148 | L39: GBP | M39: 1275 | N39: 0 | O39: =+O38+M39-N39 -> 1281.0294 | P39: XRP | R39: x
A40: ü | B40: 45012 | C40: 44916 | D40: rEb8TK3gBgk5auZkwc6sHnwrGVJH8DuaLh | E40: 547786843 | F40: TBA | G40: Aleksey Trofimov | H40: WITHDRAW | K40: =+K39+I40-J40 -> 3.8148 | M40: -1280 | N40: 0.02 | O40: =+O39+M40-N40 -> 1.0094428 | P40: XRP | Q40: =-(I39) -> 361.1116 | R40: x | U40: Consulting fee - Aleksey Trofimov
...

Sheet Kraken Ledger
P1: LOOKUP "Kraken Trades"
A2: SENT | B2: DONE | C2: TX ID | D2: DEST TAG | E2: WHO | F2: txid (filter out BLANK) | G2: refid (LOOKUP) | H2: time | I2: type | J2: subtype | K2: aclass | L2: asset | M2: amount | N2: fee | O2: balance | P2: txid | Q2: ordertxid | R2: pair | S2: time | T2: type | U2: ordertype | V2: price | W2: cost | X2: fee | Y2: vol | Z2: margin | AA2: misc | AB2: ledgers
B3: yes | E3: =_xlfn.XLOOKUP(D3,'DEST TAGs'!$A$2:$A$5,'DEST TAGs'!$B$2:$B$5,"--",0) -> -- | G3: QYP53GS-N2K7N6-UNC5Y7 | H3: 44931.559 | I3: deposit | K3: currency | L3: ZGBP | M3: 1500 | N3: 0 | P3: =_xlfn.XLOOKUP(G3,'Kraken Trades'!$A$2:$A$28,'Kraken Trades'!$A$2:$A$28,"--",0) -> -- | Q3: =_xlfn.XLOOKUP(G3,'Kraken Trades'!$A$2:$A$28,'Kraken Trades'!$B$2:$B$28,"--",0) -> -- | R3: =_xlfn.XLOOKUP(G3,'Kraken Trades'!$A$2:$A$28,'Kraken Trades'!$C$2:$C$28,"--",0) -> -- | S3: =_xlfn.XLOOKUP(G3,'Kraken Trades'!$A$2:$A$28,'Kraken Trades'!$D$2:$D$28,"--",0) -> -- | T3: =_xlfn.XLOOKUP(G3,'Kraken Trades'!$A$2:$A$28,'Kraken Trades'!$E$2:$E$28,"--",0) -> -- | U3: =_xlfn.XLOOKUP(G3,'Kraken Trades'!$A$2:$A$28,'Kraken Trades'!$F$2:$F$28,"--",0) -> -- | V3: =_xlfn.XLOOKUP(G3,'Kraken Trades'!$A$2:$A$28,'Kraken Trades'!$G$2:$G$28,"--",0) -> -- | W3: =_xlfn.XLOOKUP(G3,'Kraken Trades'!$A$2:$A$28,'Kraken Trades'!$H$2:$H$28,"--",0) -> -- | X3: =_xlfn.XLOOKUP(G3,'Kraken Trades'!$A$2:$A$28,'Kraken Trades'!$I$2:$I$28,"--",0) -> -- | Y3: =_xlfn.XLOOKUP(G3,'Kraken Trades'!$A$2:$A$28,'Kraken Trades'!$J$2:$J$28,"--",0) -> -- | Z3: =_xlfn.XLOOKUP(G3,'Kraken Trades'!$A$2:$A$28,'Kraken Trades'!$K$2:$K$28,"--",0) -> -- | AA3: =_xlfn.XLOOKUP(G3,'Kraken Trades'!$A$2:$A$28,'Kraken Trades'!$L$2:$L$28,"--",0) -> -- | AB3: =_xlfn.XLOOKUP(G3,'Kraken Trades'!$A$2:$A$28,'Kraken Trades'!$M$2:$M$28,"--",0) -> --
B4: yes | E4: =_xlfn.XLOOKUP(D4,'DEST TAGs'!$A$2:$A$5,'DEST TAGs'!$B$2:$B$5,"--",0) -> -- | F4: LBAYNS-MDQPF-FVYDWI | G4: QYP53GS-N2K7N6-UNC5Y7 | H4: 44931.567 | I4: deposit | K4: currency | L4: ZGBP | M4: 1500 | N4: 0 | O4: 1503.8148 | P4: =_xlfn.XLOOKUP(G4,'Kraken Trades'!$A$2:$A$28,'Kraken Trades'!$A$2:$A$28,"--",0) -> -- | Q4: =_xlfn.XLOOKUP(G4,'Kraken Trades'!$A$2:$A$28,'Kraken Trades'!$B$2:$B$28,"--",0) -> -- | R4: =_xlfn.XLOOKUP(G4,'Kraken Trades'!$A$2:$A$28,'Kraken Trades'!$C$2:$C$28,"--",0) -> -- | S4: =_xlfn.XLOOKUP(G4,'Kraken Trades'!$A$2:$A$28,'Kraken Trades'!$D$2:$D$28,"--",0) -> -- | T4: =_xlfn.XLOOKUP(G4,'Kraken Trades'!$A$2:$A$28,'Kraken Trades'!$E$2:$E$28,"--",0) -> -- | U4: =_xlfn.XLOOKUP(G4,'Kraken Trades'!$A$2:$A$28,'Kraken Trades'!$F$2:$F$28,"--",0) -> -- | V4: =_xlfn.XLOOKUP(G4,'Kraken Trades'!$A$2:$A$28,'Kraken Trades'!$G$2:$G$28,"--",0) -> -- | W4: =_xlfn.XLOOKUP(G4,'Kraken Trades'!$A$2:$A$28,'Kraken Trades'!$H$2:$H$28,"--",0) -> -- | X4: =_xlfn.XLOOKUP(G4,'Kraken Trades'!$A$2:$A$28,'Kraken Trades'!$I$2:$I$28,"--",0) -> -- | Y4: =_xlfn.XLOOKUP(G4,'Kraken Trades'!$A$2:$A$28,'Kraken Trades'!$J$2:$J$28,"--",0) -> -- | Z4: =_xlfn.XLOOKUP(G4,'Kraken Trades'!$A$2:$A$28,'Kraken Trades'!$K$2:$K$28,"--",0) -> -- | AA4: =_xlfn.XLOOKUP(G4,'Kraken Trades'!$A$2:$A$28,'Kraken Trades'!$L$2:$L$28,"--",0) -> -- | AB4: =_xlfn.XLOOKUP(G4,'Kraken Trades'!$A$2:$A$28,'Kraken Trades'!$M$2:$M$28,"--",0) -> --
B5: yes | E5: =_xlfn.XLOOKUP(D5,'DEST TAGs'!$A$2:$A$5,'DEST TAGs'!$B$2:$B$5,"--",0) -> -- | F5: LOC5M4-VGITG-62OW6U | G5: TVJHYS-EB5IK-4X5X33 | H5: 44931.569 | I5: trade | K5: currency | L5: ZGBP | M5: -1499.9997 | N5: 0 | O5: 3.8151 | P5: =_xlfn.XLOOKUP(G5,'Kraken Trades'!$A$2:$A$28,'Kraken Trades'!$A$2:$A$28,"--",0) -> TVJHYS-EB5IK-4X5X33 | Q5: =_xlfn.XLOOKUP(G5,'Kraken Trades'!$A$2:$A$28,'Kraken Trades'!$B$2:$B$28,"--",0) -> OX3DXP-OFPAQ-NWPXZK | R5: =_xlfn.XLOOKUP(G5,'Kraken Trades'!$A$2:$A$28,'Kraken Trades'!$C$2:$C$28,"--",0) -> XRPGBP | S5: =_xlfn.XLOOKUP(G5,'Kraken Trades'!$A$2:$A$28,'Kraken Trades'!$D$2:$D$28,"--",0) -> 0.027545139 | T5: =_xlfn.XLOOKUP(G5,'Kraken Trades'!$A$2:$A$28,'Kraken Trades'!$E$2:$E$28,"--",0) -> buy | U5: =_xlfn.XLOOKUP(G5,'Kraken Trades'!$A$2:$A$28,'Kraken Trades'!$F$2:$F$28,"--",0) -> market | V5: =_xlfn.XLOOKUP(G5,'Kraken Trades'!$A$2:$A$28,'Kraken Trades'!$G$2:$G$28,"--",0) -> 0.28462991 | W5: =_xlfn.XLOOKUP(G5,'Kraken Trades'!$A$2:$A$28,'Kraken Trades'!$H$2:$H$28,"--",0) -> 1499.9996 | X5: =_xlfn.XLOOKUP(G5,'Kraken Trades'!$A$2:$A$28,'Kraken Trades'!$I$2:$I$28,"--",0) -> 3.899999 | Y5: =_xlfn.XLOOKUP(G5,'Kraken Trades'!$A$2:$A$28,'Kraken Trades'!$J$2:$J$28,"--",0) -> 5270 | Z5: =_xlfn.XLOOKUP(G5,'Kraken Trades'!$A$2:$A$28,'Kraken Trades'!$K$2:$K$28,"--",0) -> 0 | AA5: =_xlfn.XLOOKUP(G5,'Kraken Trades'!$A$2:$A$28,'Kraken Trades'!$L$2:$L$28,"--",0) -> initiated | AB5: =_xlfn.XLOOKUP(G5,'Kraken Trades'!$A$2:$A$28,'Kraken Trades'!$M$2:$M$28,"--",0) -> LJHWVK-UM23A-Z4NP7D,LS3HC5-BWXDY-DROKXS,LOC5M4-VGITG-62OW6U
B6: yes | E6: =_xlfn.XLOOKUP(D6,'DEST TAGs'!$A$2:$A$5,'DEST TAGs'!$B$2:$B$5,"--",0) -> -- | F6: LS3HC5-BWXDY-DROKXS | G6: TVJHYS-EB5IK-4X5X33 | H6: 44931.569 | I6: trade | K6: currency | L6: XXRP | M6: 5270 | N6: 0 | O6: 5271.0094 | P6: =_xlfn.XLOOKUP(G6,'Kraken Trades'!$A$2:$A$28,'Kraken Trades'!$A$2:$A$28,"--",0) -> TVJHYS-EB5IK-4X5X33 | Q6: =_xlfn.XLOOKUP(G6,'Kraken Trades'!$A$2:$A$28,'Kraken Trades'!$B$2:$B$28,"--",0) -> OX3DXP-OFPAQ-NWPXZK | R6: =_xlfn.XLOOKUP(G6,'Kraken Trades'!$A$2:$A$28,'Kraken Trades'!$C$2:$C$28,"--",0) -> XRPGBP | S6: =_xlfn.XLOOKUP(G6,'Kraken Trades'!$A$2:$A$28,'Kraken Trades'!$D$2:$D$28,"--",0) -> 0.027545139 | T6: =_xlfn.XLOOKUP(G6,'Kraken Trades'!$A$2:$A$28,'Kraken Trades'!$E$2:$E$28,"--",0) -> buy | U6: =_xlfn.XLOOKUP(G6,'Kraken Trades'!$A$2:$A$28,'Kraken Trades'!$F$2:$F$28,"--",0) -> market | V6: =_xlfn.XLOOKUP(G6,'Kraken Trades'!$A$2:$A$28,'Kraken Trades'!$G$2:$G$28,"--",0) -> 0.28462991 | W6: =_xlfn.XLOOKUP(G6,'Kraken Trades'!$A$2:$A$28,'Kraken Trades'!$H$2:$H$28,"--",0) -> 1499.9996 | X6: =_xlfn.XLOOKUP(G6,'Kraken Trades'!$A$2:$A$28,'Kraken Trades'!$I$2:$I$28,"--",0) -> 3.899999 | Y6: =_xlfn.XLOOKUP(G6,'Kraken Trades'!$A$2:$A$28,'Kraken Trades'!$J$2:$J$28,"--",0) -> 5270 | Z6: =_xlfn.XLOOKUP(G6,'Kraken Trades'!$A$2:$A$28,'Kraken Trades'!$K$2:$K$28,"--",0) -> 0 | AA6: =_xlfn.XLOOKUP(G6,'Kraken Trades'!$A$2:$A$28,'Kraken Trades'!$L$2:$L$28,"--",0) -> initiated | AB6: =_xlfn.XLOOKUP(G6,'Kraken Trades'!$A$2:$A$28,'Kraken Trades'!$M$2:$M$28,"--",0) -> LJHWVK-UM23A-Z4NP7D,LS3HC5-BWXDY-DROKXS,LOC5M4-VGITG-62OW6U
B7: yes | E7: =_xlfn.XLOOKUP(D7,'DEST TAGs'!$A$2:$A$5,'DEST TAGs'!$B$2:$B$5,"--",0) -> -- | F7: LJHWVK-UM23A-Z4NP7D | G7: TVJHYS-EB5IK-4X5X33 | H7: 44931.569 | I7: trade | K7: currency | L7: KFEE | M7: 0 | N7: 466.73 | O7: 7910.27 | P7: =_xlfn.XLOOKUP(G7,'Kraken Trades'!$A$2:$A$28,'Kraken Trades'!$A$2:$A$28,"--",0) -> TVJHYS-EB5IK-4X5X33 | Q7: =_xlfn.XLOOKUP(G7,'Kraken Trades'!$A$2:$A$28,'Kraken Trades'!$B$2:$B$28,"--",0) -> OX3DXP-OFPAQ-NWPXZK | R7: =_xlfn.XLOOKUP(G7,'Kraken Trades'!$A$2:$A$28,'Kraken Trades'!$C$2:$C$28,"--",0) -> XRPGBP | S7: =_xlfn.XLOOKUP(G7,'Kraken Trades'!$A$2:$A$28,'Kraken Trades'!$D$2:$D$28,"--",0) -> 0.027545139 | T7: =_xlfn.XLOOKUP(G7,'Kraken Trades'!$A$2:$A$28,'Kraken Trades'!$E$2:$E$28,"--",0) -> buy | U7: =_xlfn.XLOOKUP(G7,'Kraken Trades'!$A$2:$A$28,'Kraken Trades'!$F$2:$F$28,"--",0) -> market | V7: =_xlfn.XLOOKUP(G7,'Kraken Trades'!$A$2:$A$28,'Kraken Trades'!$G$2:$G$28,"--",0) -> 0.28462991 | W7: =_xlfn.XLOOKUP(G7,'Kraken Trades'!$A$2:$A$28,'Kraken Trades'!$H$2:$H$28,"--",0) -> 1499.9996 | X7: =_xlfn.XLOOKUP(G7,'Kraken Trades'!$A$2:$A$28,'Kraken Trades'!$I$2:$I$28,"--",0) -> 3.899999 | Y7: =_xlfn.XLOOKUP(G7,'Kraken Trades'!$A$2:$A$28,'Kraken Trades'!$J$2:$J$28,"--",0) -> 5270 | Z7: =_xlfn.XLOOKUP(G7,'Kraken Trades'!$A$2:$A$28,'Kraken Trades'!$K$2:$K$28,"--",0) -> 0 | AA7: =_xlfn.XLOOKUP(G7,'Kraken Trades'!$A$2:$A$28,'Kraken Trades'!$L$2:$L$28,"--",0) -> initiated | AB7: =_xlfn.XLOOKUP(G7,'Kraken Trades'!$A$2:$A$28,'Kraken Trades'!$M$2:$M$28,"--",0) -> LJHWVK-UM23A-Z4NP7D,LS3HC5-BWXDY-DROKXS,LOC5M4-VGITG-62OW6U
B8: yes | E8: =_xlfn.XLOOKUP(D8,'DEST TAGs'!$A$2:$A$5,'DEST TAGs'!$B$2:$B$5,"--",0) -> -- | G8: AIBIVII-YHP3YE-IINMMX | H8: 44931.579 | I8: withdrawal | K8: currency | L8: XXRP | M8: -4130 | N8: 0.02 | P8: =_xlfn.XLOOKUP(G8,'Kraken Trades'!$A$2:$A$28,'Kraken Trades'!$A$2:$A$28,"--",0) -> -- | Q8: =_xlfn.XLOOKUP(G8,'Kraken Trades'!$A$2:$A$28,'Kraken Trades'!$B$2:$B$28,"--",0) -> -- | R8: =_xlfn.XLOOKUP(G8,'Kraken Trades'!$A$2:$A$28,'Kraken Trades'!$C$2:$C$28,"--",0) -> -- | S8: =_xlfn.XLOOKUP(G8,'Kraken Trades'!$A$2:$A$28,'Kraken Trades'!$D$2:$D$28,"--",0) -> -- | T8: =_xlfn.XLOOKUP(G8,'Kraken Trades'!$A$2:$A$28,'Kraken Trades'!$E$2:$E$28,"--",0) -> -- | U8: =_xlfn.XLOOKUP(G8,'Kraken Trades'!$A$2:$A$28,'Kraken Trades'!$F$2:$F$28,"--",0) -> -- | V8: =_xlfn.XLOOKUP(G8,'Kraken Trades'!$A$2:$A$28,'Kraken Trades'!$G$2:$G$28,"--",0) -> -- | W8: =_xlfn.XLOOKUP(G8,'Kraken Trades'!$A$2:$A$28,'Kraken Trades'!$H$2:$H$28,"--",0) -> -- | X8: =_xlfn.XLOOKUP(G8,'Kraken Trades'!$A$2:$A$28,'Kraken Trades'!$I$2:$I$28,"--",0) -> -- | Y8: =_xlfn.XLOOKUP(G8,'Kraken Trades'!$A$2:$A$28,'Kraken Trades'!$J$2:$J$28,"--",0) -> -- | Z8: =_xlfn.XLOOKUP(G8,'Kraken Trades'!$A$2:$A$28,'Kraken Trades'!$K$2:$K$28,"--",0) -> -- | AA8: =_xlfn.XLOOKUP(G8,'Kraken Trades'!$A$2:$A$28,'Kraken Trades'!$L$2:$L$28,"--",0) -> -- | AB8: =_xlfn.XLOOKUP(G8,'Kraken Trades'!$A$2:$A$28,'Kraken Trades'!$M$2:$M$28,"--",0) -> --
B9: yes | E9: =_xlfn.XLOOKUP(D9,'DEST TAGs'!$A$2:$A$5,'DEST TAGs'!$B$2:$B$5,"--",0) -> -- | F9: LIOUAB-5S2L2-EITVBQ | G9: AIBIVII-YHP3YE-IINMMX | H9: 44931.58 | I9: withdrawal | K9: currency | L9: XXRP | M9: -4130 | N9: 0.02 | O9: 1140.9894 | P9: =_xlfn.XLOOKUP(G9,'Kraken Trades'!$A$2:$A$28,'Kraken Trades'!$A$2:$A$28,"--",0) -> -- | Q9: =_xlfn.XLOOKUP(G9,'Kraken Trades'!$A$2:$A$28,'Kraken Trades'!$B$2:$B$28,"--",0) -> -- | R9: =_xlfn.XLOOKUP(G9,'Kraken Trades'!$A$2:$A$28,'Kraken Trades'!$C$2:$C$28,"--",0) -> -- | S9: =_xlfn.XLOOKUP(G9,'Kraken Trades'!$A$2:$A$28,'Kraken Trades'!$D$2:$D$28,"--",0) -> -- | T9: =_xlfn.XLOOKUP(G9,'Kraken Trades'!$A$2:$A$28,'Kraken Trades'!$E$2:$E$28,"--",0) -> -- | U9: =_xlfn.XLOOKUP(G9,'Kraken Trades'!$A$2:$A$28,'Kraken Trades'!$F$2:$F$28,"--",0) -> -- | V9: =_xlfn.XLOOKUP(G9,'Kraken Trades'!$A$2:$A$28,'Kraken Trades'!$G$2:$G$28,"--",0) -> -- | W9: =_xlfn.XLOOKUP(G9,'Kraken Trades'!$A$2:$A$28,'Kraken Trades'!$H$2:$H$28,"--",0) -> -- | X9: =_xlfn.XLOOKUP(G9,'Kraken Trades'!$A$2:$A$28,'Kraken Trades'!$I$2:$I$28,"--",0) -> -- | Y9: =_xlfn.XLOOKUP(G9,'Kraken Trades'!$A$2:$A$28,'Kraken Trades'!$J$2:$J$28,"--",0) -> -- | Z9: =_xlfn.XLOOKUP(G9,'Kraken Trades'!$A$2:$A$28,'Kraken Trades'!$K$2:$K$28,"--",0) -> -- | AA9: =_xlfn.XLOOKUP(G9,'Kraken Trades'!$A$2:$A$28,'Kraken Trades'!$L$2:$L$28,"--",0) -> -- | AB9: =_xlfn.XLOOKUP(G9,'Kraken Trades'!$A$2:$A$28,'Kraken Trades'!$M$2:$M$28,"--",0) -> --
B10: yes | E10: =_xlfn.XLOOKUP(D10,'DEST TAGs'!$A$2:$A$5,'DEST TAGs'!$B$2:$B$5,"--",0) -> -- | G10: AIBLWOI-K6V4V3-O252VX | H10: 44931.581 | I10: withdrawal | K10: currency | L10: XXRP | M10: -1140 | N10: 0.02 | P10: =_xlfn.XLOOKUP(G10,'Kraken Trades'!$A$2:$A$28,'Kraken Trades'!$A$2:$A$28,"--",0) -> -- | Q10: =_xlfn.XLOOKUP(G10,'Kraken Trades'!$A$2:$A$28,'Kraken Trades'!$B$2:$B$28,"--",0) -> -- | R10: =_xlfn.XLOOKUP(G10,'Kraken Trades'!$A$2:$A$28,'Kraken Trades'!$C$2:$C$28,"--",0) -> -- | S10: =_xlfn.XLOOKUP(G10,'Kraken Trades'!$A$2:$A$28,'Kraken Trades'!$D$2:$D$28,"--",0) -> -- | T10: =_xlfn.XLOOKUP(G10,'Kraken Trades'!$A$2:$A$28,'Kraken Trades'!$E$2:$E$28,"--",0) -> -- | U10: =_xlfn.XLOOKUP(G10,'Kraken Trades'!$A$2:$A$28,'Kraken Trades'!$F$2:$F$28,"--",0) -> -- | V10: =_xlfn.XLOOKUP(G10,'Kraken Trades'!$A$2:$A$28,'Kraken Trades'!$G$2:$G$28,"--",0) -> -- | W10: =_xlfn.XLOOKUP(G10,'Kraken Trades'!$A$2:$A$28,'Kraken Trades'!$H$2:$H$28,"--",0) -> -- | X10: =_xlfn.XLOOKUP(G10,'Kraken Trades'!$A$2:$A$28,'Kraken Trades'!$I$2:$I$28,"--",0) -> -- | Y10: =_xlfn.XLOOKUP(G10,'Kraken Trades'!$A$2:$A$28,'Kraken Trades'!$J$2:$J$28,"--",0) -> -- | Z10: =_xlfn.XLOOKUP(G10,'Kraken Trades'!$A$2:$A$28,'Kraken Trades'!$K$2:$K$28,"--",0) -> -- | AA10: =_xlfn.XLOOKUP(G10,'Kraken Trades'!$A$2:$A$28,'Kraken Trades'!$L$2:$L$28,"--",0) -> -- | AB10: =_xlfn.XLOOKUP(G10,'Kraken Trades'!$A$2:$A$28,'Kraken Trades'!$M$2:$M$28,"--",0) -> --
B11: yes | E11: =_xlfn.XLOOKUP(D11,'DEST TAGs'!$A$2:$A$5,'DEST TAGs'!$B$2:$B$5,"--",0) -> -- | F11: LT5VFU-GHMIT-5YX3OJ | G11: AIBLWOI-K6V4V3-O252VX | H11: 44931.582 | I11: withdrawal | K11: currency | L11: XXRP | M11: -1140 | N11: 0.02 | O11: 0.96944334 | P11: =_xlfn.XLOOKUP(G11,'Kraken Trades'!$A$2:$A$28,'Kraken Trades'!$A$2:$A$28,"--",0) -> -- | Q11: =_xlfn.XLOOKUP(G11,'Kraken Trades'!$A$2:$A$28,'Kraken Trades'!$B$2:$B$28,"--",0) -> -- | R11: =_xlfn.XLOOKUP(G11,'Kraken Trades'!$A$2:$A$28,'Kraken Trades'!$C$2:$C$28,"--",0) -> -- | S11: =_xlfn.XLOOKUP(G11,'Kraken Trades'!$A$2:$A$28,'Kraken Trades'!$D$2:$D$28,"--",0) -> -- | T11: =_xlfn.XLOOKUP(G11,'Kraken Trades'!$A$2:$A$28,'Kraken Trades'!$E$2:$E$28,"--",0) -> -- | U11: =_xlfn.XLOOKUP(G11,'Kraken Trades'!$A$2:$A$28,'Kraken Trades'!$F$2:$F$28,"--",0) -> -- | V11: =_xlfn.XLOOKUP(G11,'Kraken Trades'!$A$2:$A$28,'Kraken Trades'!$G$2:$G$28,"--",0) -> -- | W11: =_xlfn.XLOOKUP(G11,'Kraken Trades'!$A$2:$A$28,'Kraken Trades'!$H$2:$H$28,"--",0) -> -- | X11: =_xlfn.XLOOKUP(G11,'Kraken Trades'!$A$2:$A$28,'Kraken Trades'!$I$2:$I$28,"--",0) -> -- | Y11: =_xlfn.XLOOKUP(G11,'Kraken Trades'!$A$2:$A$28,'Kraken Trades'!$J$2:$J$28,"--",0) -> -- | Z11: =_xlfn.XLOOKUP(G11,'Kraken Trades'!$A$2:$A$28,'Kraken Trades'!$K$2:$K$28,"--",0) -> -- | AA11: =_xlfn.XLOOKUP(G11,'Kraken Trades'!$A$2:$A$28,'Kraken Trades'!$L$2:$L$28,"--",0) -> -- | AB11: =_xlfn.XLOOKUP(G11,'Kraken Trades'!$A$2:$A$28,'Kraken Trades'!$M$2:$M$28,"--",0) -> --
B12: yes | E12: =_xlfn.XLOOKUP(D12,'DEST TAGs'!$A$2:$A$5,'DEST TAGs'!$B$2:$B$5,"--",0) -> -- | G12: QYPDDSZ-2NWCKK-7SQZGB | H12: 44940.397 | I12: deposit | K12: currency | L12: ZGBP | M12: 300 | N12: 0 | P12: =_xlfn.XLOOKUP(G12,'Kraken Trades'!$A$2:$A$28,'Kraken Trades'!$A$2:$A$28,"--",0) -> -- | Q12: =_xlfn.XLOOKUP(G12,'Kraken Trades'!$A$2:$A$28,'Kraken Trades'!$B$2:$B$28,"--",0) -> -- | R12: =_xlfn.XLOOKUP(G12,'Kraken Trades'!$A$2:$A$28,'Kraken Trades'!$C$2:$C$28,"--",0) -> -- | S12: =_xlfn.XLOOKUP(G12,'Kraken Trades'!$A$2:$A$28,'Kraken Trades'!$D$2:$D$28,"--",0) -> -- | T12: =_xlfn.XLOOKUP(G12,'Kraken Trades'!$A$2:$A$28,'Kraken Trades'!$E$2:$E$28,"--",0) -> -- | U12: =_xlfn.XLOOKUP(G12,'Kraken Trades'!$A$2:$A$28,'Kraken Trades'!$F$2:$F$28,"--",0) -> -- | V12: =_xlfn.XLOOKUP(G12,'Kraken Trades'!$A$2:$A$28,'Kraken Trades'!$G$2:$G$28,"--",0) -> -- | W12: =_xlfn.XLOOKUP(G12,'Kraken Trades'!$A$2:$A$28,'Kraken Trades'!$H$2:$H$28,"--",0) -> -- | X12: =_xlfn.XLOOKUP(G12,'Kraken Trades'!$A$2:$A$28,'Kraken Trades'!$I$2:$I$28,"--",0) -> -- | Y12: =_xlfn.XLOOKUP(G12,'Kraken Trades'!$A$2:$A$28,'Kraken Trades'!$J$2:$J$28,"--",0) -> -- | Z12: =_xlfn.XLOOKUP(G12,'Kraken Trades'!$A$2:$A$28,'Kraken Trades'!$K$2:$K$28,"--",0) -> -- | AA12: =_xlfn.XLOOKUP(G12,'Kraken Trades'!$A$2:$A$28,'Kraken Trades'!$L$2:$L$28,"--",0) -> -- | AB12: =_xlfn.XLOOKUP(G12,'Kraken Trades'!$A$2:$A$28,'Kraken Trades'!$M$2:$M$28,"--",0) -> --
B13: yes | E13: =_xlfn.XLOOKUP(D13,'DEST TAGs'!$A$2:$A$5,'DEST TAGs'!$B$2:$B$5,"--",0) -> -- | F13: LC64M5-IU4N2-I6GYRU | G13: QYPDDSZ-2NWCKK-7SQZGB | H13: 44940.415 | I13: deposit | K13: currency | L13: ZGBP | M13: 300 | N13: 0 | O13: 303.8151 | P13: =_xlfn.XLOOKUP(G13,'Kraken Trades'!$A$2:$A$28,'Kraken Trades'!$A$2:$A$28,"--",0) -> -- | Q13: =_xlfn.XLOOKUP(G13,'Kraken Trades'!$A$2:$A$28,'Kraken Trades'!$B$2:$B$28,"--",0) -> -- | R13: =_xlfn.XLOOKUP(G13,'Kraken Trades'!$A$2:$A$28,'Kraken Trades'!$C$2:$C$28,"--",0) -> -- | S13: =_xlfn.XLOOKUP(G13,'Kraken Trades'!$A$2:$A$28,'Kraken Trades'!$D$2:$D$28,"--",0) -> -- | T13: =_xlfn.XLOOKUP(G13,'Kraken Trades'!$A$2:$A$28,'Kraken Trades'!$E$2:$E$28,"--",0) -> -- | U13: =_xlfn.XLOOKUP(G13,'Kraken Trades'!$A$2:$A$28,'Kraken Trades'!$F$2:$F$28,"--",0) -> -- | V13: =_xlfn.XLOOKUP(G13,'Kraken Trades'!$A$2:$A$28,'Kraken Trades'!$G$2:$G$28,"--",0) -> -- | W13: =_xlfn.XLOOKUP(G13,'Kraken Trades'!$A$2:$A$28,'Kraken Trades'!$H$2:$H$28,"--",0) -> -- | X13: =_xlfn.XLOOKUP(G13,'Kraken Trades'!$A$2:$A$28,'Kraken Trades'!$I$2:$I$28,"--",0) -> -- | Y13: =_xlfn.XLOOKUP(G13,'Kraken Trades'!$A$2:$A$28,'Kraken Trades'!$J$2:$J$28,"--",0) -> -- | Z13: =_xlfn.XLOOKUP(G13,'Kraken Trades'!$A$2:$A$28,'Kraken Trades'!$K$2:$K$28,"--",0) -> -- | AA13: =_xlfn.XLOOKUP(G13,'Kraken Trades'!$A$2:$A$28,'Kraken Trades'!$L$2:$L$28,"--",0) -> -- | AB13: =_xlfn.XLOOKUP(G13,'Kraken Trades'!$A$2:$A$28,'Kraken Trades'!$M$2:$M$28,"--",0) -> --
B14: yes | E14: =_xlfn.XLOOKUP(D14,'DEST TAGs'!$A$2:$A$5,'DEST TAGs'!$B$2:$B$5,"--",0) -> -- | F14: LAQ6TD-TG2HT-I27ECB | G14: TONPXD-KPDZU-5WAK7C | H14: 44940.426 | I14: trade | K14: currency | L14: ZGBP | M14: -302.1054 | N14: 0 | O14: 1.7097 | P14: =_xlfn.XLOOKUP(G14,'Kraken Trades'!$A$2:$A$28,'Kraken Trades'!$A$2:$A$28,"--",0) -> TONPXD-KPDZU-5WAK7C | Q14: =_xlfn.XLOOKUP(G14,'Kraken Trades'!$A$2:$A$28,'Kraken Trades'!$B$2:$B$28,"--",0) -> OA5AQQ-YBGEA-2YGS2M | R14: =_xlfn.XLOOKUP(G14,'Kraken Trades'!$A$2:$A$28,'Kraken Trades'!$C$2:$C$28,"--",0) -> XRPGBP | S14: =_xlfn.XLOOKUP(G14,'Kraken Trades'!$A$2:$A$28,'Kraken Trades'!$D$2:$D$28,"--",0) -> 0.0096805556 | T14: =_xlfn.XLOOKUP(G14,'Kraken Trades'!$A$2:$A$28,'Kraken Trades'!$E$2:$E$28,"--",0) -> buy | U14: =_xlfn.XLOOKUP(G14,'Kraken Trades'!$A$2:$A$28,'Kraken Trades'!$F$2:$F$28,"--",0) -> market | V14: =_xlfn.XLOOKUP(G14,'Kraken Trades'!$A$2:$A$28,'Kraken Trades'!$G$2:$G$28,"--",0) -> 0.31800562 | W14: =_xlfn.XLOOKUP(G14,'Kraken Trades'!$A$2:$A$28,'Kraken Trades'!$H$2:$H$28,"--",0) -> 302.10534 | X14: =_xlfn.XLOOKUP(G14,'Kraken Trades'!$A$2:$A$28,'Kraken Trades'!$I$2:$I$28,"--",0) -> 0.78547389 | Y14: =_xlfn.XLOOKUP(G14,'Kraken Trades'!$A$2:$A$28,'Kraken Trades'!$J$2:$J$28,"--",0) -> 950 | Z14: =_xlfn.XLOOKUP(G14,'Kraken Trades'!$A$2:$A$28,'Kraken Trades'!$K$2:$K$28,"--",0) -> 0 | AA14: =_xlfn.XLOOKUP(G14,'Kraken Trades'!$A$2:$A$28,'Kraken Trades'!$L$2:$L$28,"--",0) -> initiated | AB14: =_xlfn.XLOOKUP(G14,'Kraken Trades'!$A$2:$A$28,'Kraken Trades'!$M$2:$M$28,"--",0) -> L7GPCS-DXW2B-NSUS3D,LJGS5J-JIVT5-2JPEC4,LAQ6TD-TG2HT-I27ECB
B15: yes | E15: =_xlfn.XLOOKUP(D15,'DEST TAGs'!$A$2:$A$5,'DEST TAGs'!$B$2:$B$5,"--",0) -> -- | F15: LJGS5J-JIVT5-2JPEC4 | G15: TONPXD-KPDZU-5WAK7C | H15: 44940.426 | I15: trade | K15: currency | L15: XXRP | M15: 950 | N15: 0 | O15: 950.96944 | P15: =_xlfn.XLOOKUP(G15,'Kraken Trades'!$A$2:$A$28,'Kraken Trades'!$A$2:$A$28,"--",0) -> TONPXD-KPDZU-5WAK7C | Q15: =_xlfn.XLOOKUP(G15,'Kraken Trades'!$A$2:$A$28,'Kraken Trades'!$B$2:$B$28,"--",0) -> OA5AQQ-YBGEA-2YGS2M | R15: =_xlfn.XLOOKUP(G15,'Kraken Trades'!$A$2:$A$28,'Kraken Trades'!$C$2:$C$28,"--",0) -> XRPGBP | S15: =_xlfn.XLOOKUP(G15,'Kraken Trades'!$A$2:$A$28,'Kraken Trades'!$D$2:$D$28,"--",0) -> 0.0096805556 | T15: =_xlfn.XLOOKUP(G15,'Kraken Trades'!$A$2:$A$28,'Kraken Trades'!$E$2:$E$28,"--",0) -> buy | U15: =_xlfn.XLOOKUP(G15,'Kraken Trades'!$A$2:$A$28,'Kraken Trades'!$F$2:$F$28,"--",0) -> market | V15: =_xlfn.XLOOKUP(G15,'Kraken Trades'!$A$2:$A$28,'Kraken Trades'!$G$2:$G$28,"--",0) -> 0.31800562 | W15: =_xlfn.XLOOKUP(G15,'Kraken Trades'!$A$2:$A$28,'Kraken Trades'!$H$2:$H$28,"--",0) -> 302.10534 | X15: =_xlfn.XLOOKUP(G15,'Kraken Trades'!$A$2:$A$28,'Kraken Trades'!$I$2:$I$28,"--",0) -> 0.78547389 | Y15: =_xlfn.XLOOKUP(G15,'Kraken Trades'!$A$2:$A$28,'Kraken Trades'!$J$2:$J$28,"--",0) -> 950 | Z15: =_xlfn.XLOOKUP(G15,'Kraken Trades'!$A$2:$A$28,'Kraken Trades'!$K$2:$K$28,"--",0) -> 0 | AA15: =_xlfn.XLOOKUP(G15,'Kraken Trades'!$A$2:$A$28,'Kraken Trades'!$L$2:$L$28,"--",0) -> initiated | AB15: =_xlfn.XLOOKUP(G15,'Kraken Trades'!$A$2:$A$28,'Kraken Trades'!$M$2:$M$28,"--",0) -> L7GPCS-DXW2B-NSUS3D,LJGS5J-JIVT5-2JPEC4,LAQ6TD-TG2HT-I27ECB
B16: yes | E16: =_xlfn.XLOOKUP(D16,'DEST TAGs'!$A$2:$A$5,'DEST TAGs'!$B$2:$B$5,"--",0) -> -- | F16: L7GPCS-DXW2B-NSUS3D | G16: TONPXD-KPDZU-5WAK7C | H16: 44940.426 | I16: trade | K16: currency | L16: KFEE | M16: 0 | N16: 96.02 | O16: 7814.25 | P16: =_xlfn.XLOOKUP(G16,'Kraken Trades'!$A$2:$A$28,'Kraken Trades'!$A$2:$A$28,"--",0) -> TONPXD-KPDZU-5WAK7C | Q16: =_xlfn.XLOOKUP(G16,'Kraken Trades'!$A$2:$A$28,'Kraken Trades'!$B$2:$B$28,"--",0) -> OA5AQQ-YBGEA-2YGS2M | R16: =_xlfn.XLOOKUP(G16,'Kraken Trades'!$A$2:$A$28,'Kraken Trades'!$C$2:$C$28,"--",0) -> XRPGBP | S16: =_xlfn.XLOOKUP(G16,'Kraken Trades'!$A$2:$A$28,'Kraken Trades'!$D$2:$D$28,"--",0) -> 0.0096805556 | T16: =_xlfn.XLOOKUP(G16,'Kraken Trades'!$A$2:$A$28,'Kraken Trades'!$E$2:$E$28,"--",0) -> buy | U16: =_xlfn.XLOOKUP(G16,'Kraken Trades'!$A$2:$A$28,'Kraken Trades'!$F$2:$F$28,"--",0) -> market | V16: =_xlfn.XLOOKUP(G16,'Kraken Trades'!$A$2:$A$28,'Kraken Trades'!$G$2:$G$28,"--",0) -> 0.31800562 | W16: =_xlfn.XLOOKUP(G16,'Kraken Trades'!$A$2:$A$28,'Kraken Trades'!$H$2:$H$28,"--",0) -> 302.10534 | X16: =_xlfn.XLOOKUP(G16,'Kraken Trades'!$A$2:$A$28,'Kraken Trades'!$I$2:$I$28,"--",0) -> 0.78547389 | Y16: =_xlfn.XLOOKUP(G16,'Kraken Trades'!$A$2:$A$28,'Kraken Trades'!$J$2:$J$28,"--",0) -> 950 | Z16: =_xlfn.XLOOKUP(G16,'Kraken Trades'!$A$2:$A$28,'Kraken Trades'!$K$2:$K$28,"--",0) -> 0 | AA16: =_xlfn.XLOOKUP(G16,'Kraken Trades'!$A$2:$A$28,'Kraken Trades'!$L$2:$L$28,"--",0) -> initiated | AB16: =_xlfn.XLOOKUP(G16,'Kraken Trades'!$A$2:$A$28,'Kraken Trades'!$M$2:$M$28,"--",0) -> L7GPCS-DXW2B-NSUS3D,LJGS5J-JIVT5-2JPEC4,LAQ6TD-TG2HT-I27ECB
B17: yes | E17: =_xlfn.XLOOKUP(D17,'DEST TAGs'!$A$2:$A$5,'DEST TAGs'!$B$2:$B$5,"--",0) -> -- | G17: AIB5IWF-EUNVU3-TGM5OZ | H17: 44940.426 | I17: withdrawal | K17: currency | L17: XXRP | M17: -950 | N17: 0.02 | P17: =_xlfn.XLOOKUP(G17,'Kraken Trades'!$A$2:$A$28,'Kraken Trades'!$A$2:$A$28,"--",0) -> -- | Q17: =_xlfn.XLOOKUP(G17,'Kraken Trades'!$A$2:$A$28,'Kraken Trades'!$B$2:$B$28,"--",0) -> -- | R17: =_xlfn.XLOOKUP(G17,'Kraken Trades'!$A$2:$A$28,'Kraken Trades'!$C$2:$C$28,"--",0) -> -- | S17: =_xlfn.XLOOKUP(G17,'Kraken Trades'!$A$2:$A$28,'Kraken Trades'!$D$2:$D$28,"--",0) -> -- | T17: =_xlfn.XLOOKUP(G17,'Kraken Trades'!$A$2:$A$28,'Kraken Trades'!$E$2:$E$28,"--",0) -> -- | U17: =_xlfn.XLOOKUP(G17,'Kraken Trades'!$A$2:$A$28,'Kraken Trades'!$F$2:$F$28,"--",0) -> -- | V17: =_xlfn.XLOOKUP(G17,'Kraken Trades'!$A$2:$A$28,'Kraken Trades'!$G$2:$G$28,"--",0) -> -- | W17: =_xlfn.XLOOKUP(G17,'Kraken Trades'!$A$2:$A$28,'Kraken Trades'!$H$2:$H$28,"--",0) -> -- | X17: =_xlfn.XLOOKUP(G17,'Kraken Trades'!$A$2:$A$28,'Kraken Trades'!$I$2:$I$28,"--",0) -> -- | Y17: =_xlfn.XLOOKUP(G17,'Kraken Trades'!$A$2:$A$28,'Kraken Trades'!$J$2:$J$28,"--",0) -> -- | Z17: =_xlfn.XLOOKUP(G17,'Kraken Trades'!$A$2:$A$28,'Kraken Trades'!$K$2:$K$28,"--",0) -> -- | AA17: =_xlfn.XLOOKUP(G17,'Kraken Trades'!$A$2:$A$28,'Kraken Trades'!$L$2:$L$28,"--",0) -> -- | AB17: =_xlfn.XLOOKUP(G17,'Kraken Trades'!$A$2:$A$28,'Kraken Trades'!$M$2:$M$28,"--",0) -> --
B18: yes | E18: =_xlfn.XLOOKUP(D18,'DEST TAGs'!$A$2:$A$5,'DEST TAGs'!$B$2:$B$5,"--",0) -> -- | F18: LHORHY-JQ5AH-KIOIAE | G18: AIB5IWF-EUNVU3-TGM5OZ | H18: 44940.428 | I18: withdrawal | K18: currency | L18: XXRP | M18: -950 | N18: 0.02 | O18: 0.94944334 | P18: =_xlfn.XLOOKUP(G18,'Kraken Trades'!$A$2:$A$28,'Kraken Trades'!$A$2:$A$28,"--",0) -> -- | Q18: =_xlfn.XLOOKUP(G18,'Kraken Trades'!$A$2:$A$28,'Kraken Trades'!$B$2:$B$28,"--",0) -> -- | R18: =_xlfn.XLOOKUP(G18,'Kraken Trades'!$A$2:$A$28,'Kraken Trades'!$C$2:$C$28,"--",0) -> -- | S18: =_xlfn.XLOOKUP(G18,'Kraken Trades'!$A$2:$A$28,'Kraken Trades'!$D$2:$D$28,"--",0) -> -- | T18: =_xlfn.XLOOKUP(G18,'Kraken Trades'!$A$2:$A$28,'Kraken Trades'!$E$2:$E$28,"--",0) -> -- | U18: =_xlfn.XLOOKUP(G18,'Kraken Trades'!$A$2:$A$28,'Kraken Trades'!$F$2:$F$28,"--",0) -> -- | V18: =_xlfn.XLOOKUP(G18,'Kraken Trades'!$A$2:$A$28,'Kraken Trades'!$G$2:$G$28,"--",0) -> -- | W18: =_xlfn.XLOOKUP(G18,'Kraken Trades'!$A$2:$A$28,'Kraken Trades'!$H$2:$H$28,"--",0) -> -- | X18: =_xlfn.XLOOKUP(G18,'Kraken Trades'!$A$2:$A$28,'Kraken Trades'!$I$2:$I$28,"--",0) -> -- | Y18: =_xlfn.XLOOKUP(G18,'Kraken Trades'!$A$2:$A$28,'Kraken Trades'!$J$2:$J$28,"--",0) -> -- | Z18: =_xlfn.XLOOKUP(G18,'Kraken Trades'!$A$2:$A$28,'Kraken Trades'!$K$2:$K$28,"--",0) -> -- | AA18: =_xlfn.XLOOKUP(G18,'Kraken Trades'!$A$2:$A$28,'Kraken Trades'!$L$2:$L$28,"--",0) -> -- | AB18: =_xlfn.XLOOKUP(G18,'Kraken Trades'!$A$2:$A$28,'Kraken Trades'!$M$2:$M$28,"--",0) -> --
B19: yes | E19: =_xlfn.XLOOKUP(D19,'DEST TAGs'!$A$2:$A$5,'DEST TAGs'!$B$2:$B$5,"--",0) -> -- | G19: QYPHCEQ-52QCIX-MFW6DR | H19: 44945.444 | I19: deposit | K19: currency | L19: ZGBP | M19: 850 | N19: 0 | P19: =_xlfn.XLOOKUP(G19,'Kraken Trades'!$A$2:$A$28,'Kraken Trades'!$A$2:$A$28,"--",0) -> -- | Q19: =_xlfn.XLOOKUP(G19,'Kraken Trades'!$A$2:$A$28,'Kraken Trades'!$B$2:$B$28,"--",0) -> -- | R19: =_xlfn.XLOOKUP(G19,'Kraken Trades'!$A$2:$A$28,'Kraken Trades'!$C$2:$C$28,"--",0) -> -- | S19: =_xlfn.XLOOKUP(G19,'Kraken Trades'!$A$2:$A$28,'Kraken Trades'!$D$2:$D$28,"--",0) -> -- | T19: =_xlfn.XLOOKUP(G19,'Kraken Trades'!$A$2:$A$28,'Kraken Trades'!$E$2:$E$28,"--",0) -> -- | U19: =_xlfn.XLOOKUP(G19,'Kraken Trades'!$A$2:$A$28,'Kraken Trades'!$F$2:$F$28,"--",0) -> -- | V19: =_xlfn.XLOOKUP(G19,'Kraken Trades'!$A$2:$A$28,'Kraken Trades'!$G$2:$G$28,"--",0) -> -- | W19: =_xlfn.XLOOKUP(G19,'Kraken Trades'!$A$2:$A$28,'Kraken Trades'!$H$2:$H$28,"--",0) -> -- | X19: =_xlfn.XLOOKUP(G19,'Kraken Trades'!$A$2:$A$28,'Kraken Trades'!$I$2:$I$28,"--",0) -> -- | Y19: =_xlfn.XLOOKUP(G19,'Kraken Trades'!$A$2:$A$28,'Kraken Trades'!$J$2:$J$28,"--",0) -> -- | Z19: =_xlfn.XLOOKUP(G19,'Kraken Trades'!$A$2:$A$28,'Kraken Trades'!$K$2:$K$28,"--",0) -> -- | AA19: =_xlfn.XLOOKUP(G19,'Kraken Trades'!$A$2:$A$28,'Kraken Trades'!$L$2:$L$28,"--",0) -> -- | AB19: =_xlfn.XLOOKUP(G19,'Kraken Trades'!$A$2:$A$28,'Kraken Trades'!$M$2:$M$28,"--",0) -> --
B20: yes | E20: =_xlfn.XLOOKUP(D20,'DEST TAGs'!$A$2:$A$5,'DEST TAGs'!$B$2:$B$5,"--",0) -> -- | F20: LO7JZE-IQ7D6-HDBDJV | G20: QYPHCEQ-52QCIX-MFW6DR | H20: 44945.45 | I20: deposit | K20: currency | L20: ZGBP | M20: 850 | N20: 0 | O20: 851.7097 | P20: =_xlfn.XLOOKUP(G20,'Kraken Trades'!$A$2:$A$28,'Kraken Trades'!$A$2:$A$28,"--",0) -> -- | Q20: =_xlfn.XLOOKUP(G20,'Kraken Trades'!$A$2:$A$28,'Kraken Trades'!$B$2:$B$28,"--",0) -> -- | R20: =_xlfn.XLOOKUP(G20,'Kraken Trades'!$A$2:$A$28,'Kraken Trades'!$C$2:$C$28,"--",0) -> -- | S20: =_xlfn.XLOOKUP(G20,'Kraken Trades'!$A$2:$A$28,'Kraken Trades'!$D$2:$D$28,"--",0) -> -- | T20: =_xlfn.XLOOKUP(G20,'Kraken Trades'!$A$2:$A$28,'Kraken Trades'!$E$2:$E$28,"--",0) -> -- | U20: =_xlfn.XLOOKUP(G20,'Kraken Trades'!$A$2:$A$28,'Kraken Trades'!$F$2:$F$28,"--",0) -> -- | V20: =_xlfn.XLOOKUP(G20,'Kraken Trades'!$A$2:$A$28,'Kraken Trades'!$G$2:$G$28,"--",0) -> -- | W20: =_xlfn.XLOOKUP(G20,'Kraken Trades'!$A$2:$A$28,'Kraken Trades'!$H$2:$H$28,"--",0) -> -- | X20: =_xlfn.XLOOKUP(G20,'Kraken Trades'!$A$2:$A$28,'Kraken Trades'!$I$2:$I$28,"--",0) -> -- | Y20: =_xlfn.XLOOKUP(G20,'Kraken Trades'!$A$2:$A$28,'Kraken Trades'!$J$2:$J$28,"--",0) -> -- | Z20: =_xlfn.XLOOKUP(G20,'Kraken Trades'!$A$2:$A$28,'Kraken Trades'!$K$2:$K$28,"--",0) -> -- | AA20: =_xlfn.XLOOKUP(G20,'Kraken Trades'!$A$2:$A$28,'Kraken Trades'!$L$2:$L$28,"--",0) -> -- | AB20: =_xlfn.XLOOKUP(G20,'Kraken Trades'!$A$2:$A$28,'Kraken Trades'!$M$2:$M$28,"--",0) -> --
B21: yes | E21: =_xlfn.XLOOKUP(D21,'DEST TAGs'!$A$2:$A$5,'DEST TAGs'!$B$2:$B$5,"--",0) -> -- | F21: LQ5Y6F-GXLDN-OQIMCY | G21: TFUFLH-JICVN-QIRXBC | H21: 44945.452 | I21: trade | K21: currency | L21: ZGBP | M21: -850.2842 | N21: 0 | O21: 1.4255 | P21: =_xlfn.XLOOKUP(G21,'Kraken Trades'!$A$2:$A$28,'Kraken Trades'!$A$2:$A$28,"--",0) -> TFUFLH-JICVN-QIRXBC | Q21: =_xlfn.XLOOKUP(G21,'Kraken Trades'!$A$2:$A$28,'Kraken Trades'!$B$2:$B$28,"--",0) -> ON4G3V-EWYBS-PENEAQ | R21: =_xlfn.XLOOKUP(G21,'Kraken Trades'!$A$2:$A$28,'Kraken Trades'!$C$2:$C$28,"--",0) -> XRPGBP | S21: =_xlfn.XLOOKUP(G21,'Kraken Trades'!$A$2:$A$28,'Kraken Trades'!$D$2:$D$28,"--",0) -> 0.035511574 | T21: =_xlfn.XLOOKUP(G21,'Kraken Trades'!$A$2:$A$28,'Kraken Trades'!$E$2:$E$28,"--",0) -> buy | U21: =_xlfn.XLOOKUP(G21,'Kraken Trades'!$A$2:$A$28,'Kraken Trades'!$F$2:$F$28,"--",0) -> market | V21: =_xlfn.XLOOKUP(G21,'Kraken Trades'!$A$2:$A$28,'Kraken Trades'!$G$2:$G$28,"--",0) -> 0.31492011 | W21: =_xlfn.XLOOKUP(G21,'Kraken Trades'!$A$2:$A$28,'Kraken Trades'!$H$2:$H$28,"--",0) -> 850.28431 | X21: =_xlfn.XLOOKUP(G21,'Kraken Trades'!$A$2:$A$28,'Kraken Trades'!$I$2:$I$28,"--",0) -> 2.2107392 | Y21: =_xlfn.XLOOKUP(G21,'Kraken Trades'!$A$2:$A$28,'Kraken Trades'!$J$2:$J$28,"--",0) -> 2700 | Z21: =_xlfn.XLOOKUP(G21,'Kraken Trades'!$A$2:$A$28,'Kraken Trades'!$K$2:$K$28,"--",0) -> 0 | AA21: =_xlfn.XLOOKUP(G21,'Kraken Trades'!$A$2:$A$28,'Kraken Trades'!$L$2:$L$28,"--",0) -> initiated | AB21: =_xlfn.XLOOKUP(G21,'Kraken Trades'!$A$2:$A$28,'Kraken Trades'!$M$2:$M$28,"--",0) -> L2AZFP-MHOGI-Z6IC76,LQENTR-CXN3S-V2AFUZ,LQ5Y6F-GXLDN-OQIMCY
B22: yes | E22: =_xlfn.XLOOKUP(D22,'DEST TAGs'!$A$2:$A$5,'DEST TAGs'!$B$2:$B$5,"--",0) -> -- | F22: LQENTR-CXN3S-V2AFUZ | G22: TFUFLH-JICVN-QIRXBC | H22: 44945.452 | I22: trade | K22: currency | L22: XXRP | M22: 2700 | N22: 0 | O22: 2700.9494 | P22: =_xlfn.XLOOKUP(G22,'Kraken Trades'!$A$2:$A$28,'Kraken Trades'!$A$2:$A$28,"--",0) -> TFUFLH-JICVN-QIRXBC | Q22: =_xlfn.XLOOKUP(G22,'Kraken Trades'!$A$2:$A$28,'Kraken Trades'!$B$2:$B$28,"--",0) -> ON4G3V-EWYBS-PENEAQ | R22: =_xlfn.XLOOKUP(G22,'Kraken Trades'!$A$2:$A$28,'Kraken Trades'!$C$2:$C$28,"--",0) -> XRPGBP | S22: =_xlfn.XLOOKUP(G22,'Kraken Trades'!$A$2:$A$28,'Kraken Trades'!$D$2:$D$28,"--",0) -> 0.035511574 | T22: =_xlfn.XLOOKUP(G22,'Kraken Trades'!$A$2:$A$28,'Kraken Trades'!$E$2:$E$28,"--",0) -> buy | U22: =_xlfn.XLOOKUP(G22,'Kraken Trades'!$A$2:$A$28,'Kraken Trades'!$F$2:$F$28,"--",0) -> market | V22: =_xlfn.XLOOKUP(G22,'Kraken Trades'!$A$2:$A$28,'Kraken Trades'!$G$2:$G$28,"--",0) -> 0.31492011 | W22: =_xlfn.XLOOKUP(G22,'Kraken Trades'!$A$2:$A$28,'Kraken Trades'!$H$2:$H$28,"--",0) -> 850.28431 | X22: =_xlfn.XLOOKUP(G22,'Kraken Trades'!$A$2:$A$28,'Kraken Trades'!$I$2:$I$28,"--",0) -> 2.2107392 | Y22: =_xlfn.XLOOKUP(G22,'Kraken Trades'!$A$2:$A$28,'Kraken Trades'!$J$2:$J$28,"--",0) -> 2700 | Z22: =_xlfn.XLOOKUP(G22,'Kraken Trades'!$A$2:$A$28,'Kraken Trades'!$K$2:$K$28,"--",0) -> 0 | AA22: =_xlfn.XLOOKUP(G22,'Kraken Trades'!$A$2:$A$28,'Kraken Trades'!$L$2:$L$28,"--",0) -> initiated | AB22: =_xlfn.XLOOKUP(G22,'Kraken Trades'!$A$2:$A$28,'Kraken Trades'!$M$2:$M$28,"--",0) -> L2AZFP-MHOGI-Z6IC76,LQENTR-CXN3S-V2AFUZ,LQ5Y6F-GXLDN-OQIMCY
B23: yes | E23: =_xlfn.XLOOKUP(D23,'DEST TAGs'!$A$2:$A$5,'DEST TAGs'!$B$2:$B$5,"--",0) -> -- | F23: L2AZFP-MHOGI-Z6IC76 | G23: TFUFLH-JICVN-QIRXBC | H23: 44945.452 | I23: trade | K23: currency | L23: KFEE | M23: 0 | N23: 272.55 | O23: 7541.7 | P23: =_xlfn.XLOOKUP(G23,'Kraken Trades'!$A$2:$A$28,'Kraken Trades'!$A$2:$A$28,"--",0) -> TFUFLH-JICVN-QIRXBC | Q23: =_xlfn.XLOOKUP(G23,'Kraken Trades'!$A$2:$A$28,'Kraken Trades'!$B$2:$B$28,"--",0) -> ON4G3V-EWYBS-PENEAQ | R23: =_xlfn.XLOOKUP(G23,'Kraken Trades'!$A$2:$A$28,'Kraken Trades'!$C$2:$C$28,"--",0) -> XRPGBP | S23: =_xlfn.XLOOKUP(G23,'Kraken Trades'!$A$2:$A$28,'Kraken Trades'!$D$2:$D$28,"--",0) -> 0.035511574 | T23: =_xlfn.XLOOKUP(G23,'Kraken Trades'!$A$2:$A$28,'Kraken Trades'!$E$2:$E$28,"--",0) -> buy | U23: =_xlfn.XLOOKUP(G23,'Kraken Trades'!$A$2:$A$28,'Kraken Trades'!$F$2:$F$28,"--",0) -> market | V23: =_xlfn.XLOOKUP(G23,'Kraken Trades'!$A$2:$A$28,'Kraken Trades'!$G$2:$G$28,"--",0) -> 0.31492011 | W23: =_xlfn.XLOOKUP(G23,'Kraken Trades'!$A$2:$A$28,'Kraken Trades'!$H$2:$H$28,"--",0) -> 850.28431 | X23: =_xlfn.XLOOKUP(G23,'Kraken Trades'!$A$2:$A$28,'Kraken Trades'!$I$2:$I$28,"--",0) -> 2.2107392 | Y23: =_xlfn.XLOOKUP(G23,'Kraken Trades'!$A$2:$A$28,'Kraken Trades'!$J$2:$J$28,"--",0) -> 2700 | Z23: =_xlfn.XLOOKUP(G23,'Kraken Trades'!$A$2:$A$28,'Kraken Trades'!$K$2:$K$28,"--",0) -> 0 | AA23: =_xlfn.XLOOKUP(G23,'Kraken Trades'!$A$2:$A$28,'Kraken Trades'!$L$2:$L$28,"--",0) -> initiated | AB23: =_xlfn.XLOOKUP(G23,'Kraken Trades'!$A$2:$A$28,'Kraken Trades'!$M$2:$M$28,"--",0) -> L2AZFP-MHOGI-Z6IC76,LQENTR-CXN3S-V2AFUZ,LQ5Y6F-GXLDN-OQIMCY
B24: yes | E24: =_xlfn.XLOOKUP(D24,'DEST TAGs'!$A$2:$A$5,'DEST TAGs'!$B$2:$B$5,"--",0) -> -- | G24: AIBR3RN-RCA564-DEIYYX | H24: 44945.452 | I24: withdrawal | K24: currency | L24: XXRP | M24: -2700 | N24: 0.02 | P24: =_xlfn.XLOOKUP(G24,'Kraken Trades'!$A$2:$A$28,'Kraken Trades'!$A$2:$A$28,"--",0) -> -- | Q24: =_xlfn.XLOOKUP(G24,'Kraken Trades'!$A$2:$A$28,'Kraken Trades'!$B$2:$B$28,"--",0) -> -- | R24: =_xlfn.XLOOKUP(G24,'Kraken Trades'!$A$2:$A$28,'Kraken Trades'!$C$2:$C$28,"--",0) -> -- | S24: =_xlfn.XLOOKUP(G24,'Kraken Trades'!$A$2:$A$28,'Kraken Trades'!$D$2:$D$28,"--",0) -> -- | T24: =_xlfn.XLOOKUP(G24,'Kraken Trades'!$A$2:$A$28,'Kraken Trades'!$E$2:$E$28,"--",0) -> -- | U24: =_xlfn.XLOOKUP(G24,'Kraken Trades'!$A$2:$A$28,'Kraken Trades'!$F$2:$F$28,"--",0) -> -- | V24: =_xlfn.XLOOKUP(G24,'Kraken Trades'!$A$2:$A$28,'Kraken Trades'!$G$2:$G$28,"--",0) -> -- | W24: =_xlfn.XLOOKUP(G24,'Kraken Trades'!$A$2:$A$28,'Kraken Trades'!$H$2:$H$28,"--",0) -> -- | X24: =_xlfn.XLOOKUP(G24,'Kraken Trades'!$A$2:$A$28,'Kraken Trades'!$I$2:$I$28,"--",0) -> -- | Y24: =_xlfn.XLOOKUP(G24,'Kraken Trades'!$A$2:$A$28,'Kraken Trades'!$J$2:$J$28,"--",0) -> -- | Z24: =_xlfn.XLOOKUP(G24,'Kraken Trades'!$A$2:$A$28,'Kraken Trades'!$K$2:$K$28,"--",0) -> -- | AA24: =_xlfn.XLOOKUP(G24,'Kraken Trades'!$A$2:$A$28,'Kraken Trades'!$L$2:$L$28,"--",0) -> -- | AB24: =_xlfn.XLOOKUP(G24,'Kraken Trades'!$A$2:$A$28,'Kraken Trades'!$M$2:$M$28,"--",0) -> --
B25: yes | E25: =_xlfn.XLOOKUP(D25,'DEST TAGs'!$A$2:$A$5,'DEST TAGs'!$B$2:$B$5,"--",0) -> -- | F25: LB3VDZ-3XU4V-F5JKI3 | G25: AIBR3RN-RCA564-DEIYYX | H25: 44945.453 | I25: withdrawal | K25: currency | L25: XXRP | M25: -2700 | N25: 0.02 | O25: 0.92944334 | P25: =_xlfn.XLOOKUP(G25,'Kraken Trades'!$A$2:$A$28,'Kraken Trades'!$A$2:$A$28,"--",0) -> -- | Q25: =_xlfn.XLOOKUP(G25,'Kraken Trades'!$A$2:$A$28,'Kraken Trades'!$B$2:$B$28,"--",0) -> -- | R25: =_xlfn.XLOOKUP(G25,'Kraken Trades'!$A$2:$A$28,'Kraken Trades'!$C$2:$C$28,"--",0) -> -- | S25: =_xlfn.XLOOKUP(G25,'Kraken Trades'!$A$2:$A$28,'Kraken Trades'!$D$2:$D$28,"--",0) -> -- | T25: =_xlfn.XLOOKUP(G25,'Kraken Trades'!$A$2:$A$28,'Kraken Trades'!$E$2:$E$28,"--",0) -> -- | U25: =_xlfn.XLOOKUP(G25,'Kraken Trades'!$A$2:$A$28,'Kraken Trades'!$F$2:$F$28,"--",0) -> -- | V25: =_xlfn.XLOOKUP(G25,'Kraken Trades'!$A$2:$A$28,'Kraken Trades'!$G$2:$G$28,"--",0) -> -- | W25: =_xlfn.XLOOKUP(G25,'Kraken Trades'!$A$2:$A$28,'Kraken Trades'!$H$2:$H$28,"--",0) -> -- | X25: =_xlfn.XLOOKUP(G25,'Kraken Trades'!$A$2:$A$28,'Kraken Trades'!$I$2:$I$28,"--",0) -> -- | Y25: =_xlfn.XLOOKUP(G25,'Kraken Trades'!$A$2:$A$28,'Kraken Trades'!$J$2:$J$28,"--",0) -> -- | Z25: =_xlfn.XLOOKUP(G25,'Kraken Trades'!$A$2:$A$28,'Kraken Trades'!$K$2:$K$28,"--",0) -> -- | AA25: =_xlfn.XLOOKUP(G25,'Kraken Trades'!$A$2:$A$28,'Kraken Trades'!$L$2:$L$28,"--",0) -> -- | AB25: =_xlfn.XLOOKUP(G25,'Kraken Trades'!$A$2:$A$28,'Kraken Trades'!$M$2:$M$28,"--",0) -> --
B26: yes | E26: =_xlfn.XLOOKUP(D26,'DEST TAGs'!$A$2:$A$5,'DEST TAGs'!$B$2:$B$5,"--",0) -> -- | G26: QYPVSFN-YLYON6-TG7CCM | H26: 44954.46 | I26: deposit | K26: currency | L26: ZGBP | M26: 175 | N26: 0 | P26: =_xlfn.XLOOKUP(G26,'Kraken Trades'!$A$2:$A$28,'Kraken Trades'!$A$2:$A$28,"--",0) -> -- | Q26: =_xlfn.XLOOKUP(G26,'Kraken Trades'!$A$2:$A$28,'Kraken Trades'!$B$2:$B$28,"--",0) -> -- | R26: =_xlfn.XLOOKUP(G26,'Kraken Trades'!$A$2:$A$28,'Kraken Trades'!$C$2:$C$28,"--",0) -> -- | S26: =_xlfn.XLOOKUP(G26,'Kraken Trades'!$A$2:$A$28,'Kraken Trades'!$D$2:$D$28,"--",0) -> -- | T26: =_xlfn.XLOOKUP(G26,'Kraken Trades'!$A$2:$A$28,'Kraken Trades'!$E$2:$E$28,"--",0) -> -- | U26: =_xlfn.XLOOKUP(G26,'Kraken Trades'!$A$2:$A$28,'Kraken Trades'!$F$2:$F$28,"--",0) -> -- | V26: =_xlfn.XLOOKUP(G26,'Kraken Trades'!$A$2:$A$28,'Kraken Trades'!$G$2:$G$28,"--",0) -> -- | W26: =_xlfn.XLOOKUP(G26,'Kraken Trades'!$A$2:$A$28,'Kraken Trades'!$H$2:$H$28,"--",0) -> -- | X26: =_xlfn.XLOOKUP(G26,'Kraken Trades'!$A$2:$A$28,'Kraken Trades'!$I$2:$I$28,"--",0) -> -- | Y26: =_xlfn.XLOOKUP(G26,'Kraken Trades'!$A$2:$A$28,'Kraken Trades'!$J$2:$J$28,"--",0) -> -- | Z26: =_xlfn.XLOOKUP(G26,'Kraken Trades'!$A$2:$A$28,'Kraken Trades'!$K$2:$K$28,"--",0) -> -- | AA26: =_xlfn.XLOOKUP(G26,'Kraken Trades'!$A$2:$A$28,'Kraken Trades'!$L$2:$L$28,"--",0) -> -- | AB26: =_xlfn.XLOOKUP(G26,'Kraken Trades'!$A$2:$A$28,'Kraken Trades'!$M$2:$M$28,"--",0) -> --
B27: yes | E27: =_xlfn.XLOOKUP(D27,'DEST TAGs'!$A$2:$A$5,'DEST TAGs'!$B$2:$B$5,"--",0) -> -- | F27: LOE2FQ-X6PEM-AQH2PB | G27: QYPVSFN-YLYON6-TG7CCM | H27: 44954.501 | I27: deposit | K27: currency | L27: ZGBP | M27: 175 | N27: 0 | O27: 176.4255 | P27: =_xlfn.XLOOKUP(G27,'Kraken Trades'!$A$2:$A$28,'Kraken Trades'!$A$2:$A$28,"--",0) -> -- | Q27: =_xlfn.XLOOKUP(G27,'Kraken Trades'!$A$2:$A$28,'Kraken Trades'!$B$2:$B$28,"--",0) -> -- | R27: =_xlfn.XLOOKUP(G27,'Kraken Trades'!$A$2:$A$28,'Kraken Trades'!$C$2:$C$28,"--",0) -> -- | S27: =_xlfn.XLOOKUP(G27,'Kraken Trades'!$A$2:$A$28,'Kraken Trades'!$D$2:$D$28,"--",0) -> -- | T27: =_xlfn.XLOOKUP(G27,'Kraken Trades'!$A$2:$A$28,'Kraken Trades'!$E$2:$E$28,"--",0) -> -- | U27: =_xlfn.XLOOKUP(G27,'Kraken Trades'!$A$2:$A$28,'Kraken Trades'!$F$2:$F$28,"--",0) -> -- | V27: =_xlfn.XLOOKUP(G27,'Kraken Trades'!$A$2:$A$28,'Kraken Trades'!$G$2:$G$28,"--",0) -> -- | W27: =_xlfn.XLOOKUP(G27,'Kraken Trades'!$A$2:$A$28,'Kraken Trades'!$H$2:$H$28,"--",0) -> -- | X27: =_xlfn.XLOOKUP(G27,'Kraken Trades'!$A$2:$A$28,'Kraken Trades'!$I$2:$I$28,"--",0) -> -- | Y27: =_xlfn.XLOOKUP(G27,'Kraken Trades'!$A$2:$A$28,'Kraken Trades'!$J$2:$J$28,"--",0) -> -- | Z27: =_xlfn.XLOOKUP(G27,'Kraken Trades'!$A$2:$A$28,'Kraken Trades'!$K$2:$K$28,"--",0) -> -- | AA27: =_xlfn.XLOOKUP(G27,'Kraken Trades'!$A$2:$A$28,'Kraken Trades'!$L$2:$L$28,"--",0) -> -- | AB27: =_xlfn.XLOOKUP(G27,'Kraken Trades'!$A$2:$A$28,'Kraken Trades'!$M$2:$M$28,"--",0) -> --
B28: yes | E28: =_xlfn.XLOOKUP(D28,'DEST TAGs'!$A$2:$A$5,'DEST TAGs'!$B$2:$B$5,"--",0) -> -- | F28: LNTCL3-MS5IQ-JHFPLF | G28: TS6ESC-QJCTE-7REB62 | H28: 44954.504 | I28: trade | K28: currency | L28: ZGBP | M28: -175.3876 | N28: 0 | O28: 1.0379 | P28: =_xlfn.XLOOKUP(G28,'Kraken Trades'!$A$2:$A$28,'Kraken Trades'!$A$2:$A$28,"--",0) -> TS6ESC-QJCTE-7REB62 | Q28: =_xlfn.XLOOKUP(G28,'Kraken Trades'!$A$2:$A$28,'Kraken Trades'!$B$2:$B$28,"--",0) -> OVMH6P-VMU7P-E44AOJ | R28: =_xlfn.XLOOKUP(G28,'Kraken Trades'!$A$2:$A$28,'Kraken Trades'!$C$2:$C$28,"--",0) -> XRPGBP | S28: =_xlfn.XLOOKUP(G28,'Kraken Trades'!$A$2:$A$28,'Kraken Trades'!$D$2:$D$28,"--",0) -> 0.0046458333 | T28: =_xlfn.XLOOKUP(G28,'Kraken Trades'!$A$2:$A$28,'Kraken Trades'!$E$2:$E$28,"--",0) -> buy | U28: =_xlfn.XLOOKUP(G28,'Kraken Trades'!$A$2:$A$28,'Kraken Trades'!$F$2:$F$28,"--",0) -> market | V28: =_xlfn.XLOOKUP(G28,'Kraken Trades'!$A$2:$A$28,'Kraken Trades'!$G$2:$G$28,"--",0) -> 0.33092 | W28: =_xlfn.XLOOKUP(G28,'Kraken Trades'!$A$2:$A$28,'Kraken Trades'!$H$2:$H$28,"--",0) -> 175.3876 | X28: =_xlfn.XLOOKUP(G28,'Kraken Trades'!$A$2:$A$28,'Kraken Trades'!$I$2:$I$28,"--",0) -> 0.45600776 | Y28: =_xlfn.XLOOKUP(G28,'Kraken Trades'!$A$2:$A$28,'Kraken Trades'!$J$2:$J$28,"--",0) -> 530 | Z28: =_xlfn.XLOOKUP(G28,'Kraken Trades'!$A$2:$A$28,'Kraken Trades'!$K$2:$K$28,"--",0) -> 0 | AA28: =_xlfn.XLOOKUP(G28,'Kraken Trades'!$A$2:$A$28,'Kraken Trades'!$L$2:$L$28,"--",0) -> initiated | AB28: =_xlfn.XLOOKUP(G28,'Kraken Trades'!$A$2:$A$28,'Kraken Trades'!$M$2:$M$28,"--",0) -> L7JNEK-NXJOR-PGHOYD,LKUCJL-B6QP6-HVTZSZ,LNTCL3-MS5IQ-JHFPLF
B29: yes | E29: =_xlfn.XLOOKUP(D29,'DEST TAGs'!$A$2:$A$5,'DEST TAGs'!$B$2:$B$5,"--",0) -> -- | F29: LKUCJL-B6QP6-HVTZSZ | G29: TS6ESC-QJCTE-7REB62 | H29: 44954.504 | I29: trade | K29: currency | L29: XXRP | M29: 530 | N29: 0 | O29: 530.92944 | P29: =_xlfn.XLOOKUP(G29,'Kraken Trades'!$A$2:$A$28,'Kraken Trades'!$A$2:$A$28,"--",0) -> TS6ESC-QJCTE-7REB62 | Q29: =_xlfn.XLOOKUP(G29,'Kraken Trades'!$A$2:$A$28,'Kraken Trades'!$B$2:$B$28,"--",0) -> OVMH6P-VMU7P-E44AOJ | R29: =_xlfn.XLOOKUP(G29,'Kraken Trades'!$A$2:$A$28,'Kraken Trades'!$C$2:$C$28,"--",0) -> XRPGBP | S29: =_xlfn.XLOOKUP(G29,'Kraken Trades'!$A$2:$A$28,'Kraken Trades'!$D$2:$D$28,"--",0) -> 0.0046458333 | T29: =_xlfn.XLOOKUP(G29,'Kraken Trades'!$A$2:$A$28,'Kraken Trades'!$E$2:$E$28,"--",0) -> buy | U29: =_xlfn.XLOOKUP(G29,'Kraken Trades'!$A$2:$A$28,'Kraken Trades'!$F$2:$F$28,"--",0) -> market | V29: =_xlfn.XLOOKUP(G29,'Kraken Trades'!$A$2:$A$28,'Kraken Trades'!$G$2:$G$28,"--",0) -> 0.33092 | W29: =_xlfn.XLOOKUP(G29,'Kraken Trades'!$A$2:$A$28,'Kraken Trades'!$H$2:$H$28,"--",0) -> 175.3876 | X29: =_xlfn.XLOOKUP(G29,'Kraken Trades'!$A$2:$A$28,'Kraken Trades'!$I$2:$I$28,"--",0) -> 0.45600776 | Y29: =_xlfn.XLOOKUP(G29,'Kraken Trades'!$A$2:$A$28,'Kraken Trades'!$J$2:$J$28,"--",0) -> 530 | Z29: =_xlfn.XLOOKUP(G29,'Kraken Trades'!$A$2:$A$28,'Kraken Trades'!$K$2:$K$28,"--",0) -> 0 | AA29: =_xlfn.XLOOKUP(G29,'Kraken Trades'!$A$2:$A$28,'Kraken Trades'!$L$2:$L$28,"--",0) -> initiated | AB29: =_xlfn.XLOOKUP(G29,'Kraken Trades'!$A$2:$A$28,'Kraken Trades'!$M$2:$M$28,"--",0) -> L7JNEK-NXJOR-PGHOYD,LKUCJL-B6QP6-HVTZSZ,LNTCL3-MS5IQ-JHFPLF
B30: yes | E30: =_xlfn.XLOOKUP(D30,'DEST TAGs'!$A$2:$A$5,'DEST TAGs'!$B$2:$B$5,"--",0) -> -- | F30: L7JNEK-NXJOR-PGHOYD | G30: TS6ESC-QJCTE-7REB62 | H30: 44954.504 | I30: trade | K30: currency | L30: KFEE | M30: 0 | N30: 56.51 | O30: 7485.19 | P30: =_xlfn.XLOOKUP(G30,'Kraken Trades'!$A$2:$A$28,'Kraken Trades'!$A$2:$A$28,"--",0) -> TS6ESC-QJCTE-7REB62 | Q30: =_xlfn.XLOOKUP(G30,'Kraken Trades'!$A$2:$A$28,'Kraken Trades'!$B$2:$B$28,"--",0) -> OVMH6P-VMU7P-E44AOJ | R30: =_xlfn.XLOOKUP(G30,'Kraken Trades'!$A$2:$A$28,'Kraken Trades'!$C$2:$C$28,"--",0) -> XRPGBP | S30: =_xlfn.XLOOKUP(G30,'Kraken Trades'!$A$2:$A$28,'Kraken Trades'!$D$2:$D$28,"--",0) -> 0.0046458333 | T30: =_xlfn.XLOOKUP(G30,'Kraken Trades'!$A$2:$A$28,'Kraken Trades'!$E$2:$E$28,"--",0) -> buy | U30: =_xlfn.XLOOKUP(G30,'Kraken Trades'!$A$2:$A$28,'Kraken Trades'!$F$2:$F$28,"--",0) -> market | V30: =_xlfn.XLOOKUP(G30,'Kraken Trades'!$A$2:$A$28,'Kraken Trades'!$G$2:$G$28,"--",0) -> 0.33092 | W30: =_xlfn.XLOOKUP(G30,'Kraken Trades'!$A$2:$A$28,'Kraken Trades'!$H$2:$H$28,"--",0) -> 175.3876 | X30: =_xlfn.XLOOKUP(G30,'Kraken Trades'!$A$2:$A$28,'Kraken Trades'!$I$2:$I$28,"--",0) -> 0.45600776 | Y30: =_xlfn.XLOOKUP(G30,'Kraken Trades'!$A$2:$A$28,'Kraken Trades'!$J$2:$J$28,"--",0) -> 530 | Z30: =_xlfn.XLOOKUP(G30,'Kraken Trades'!$A$2:$A$28,'Kraken Trades'!$K$2:$K$28,"--",0) -> 0 | AA30: =_xlfn.XLOOKUP(G30,'Kraken Trades'!$A$2:$A$28,'Kraken Trades'!$L$2:$L$28,"--",0) -> initiated | AB30: =_xlfn.XLOOKUP(G30,'Kraken Trades'!$A$2:$A$28,'Kraken Trades'!$M$2:$M$28,"--",0) -> L7JNEK-NXJOR-PGHOYD,LKUCJL-B6QP6-HVTZSZ,LNTCL3-MS5IQ-JHFPLF
B31: yes | E31: =_xlfn.XLOOKUP(D31,'DEST TAGs'!$A$2:$A$5,'DEST TAGs'!$B$2:$B$5,"--",0) -> -- | G31: AIBFEVW-VQSPR2-XZQSSP | H31: 44954.505 | I31: withdrawal | K31: currency | L31: XXRP | M31: -530 | N31: 0.02 | P31: =_xlfn.XLOOKUP(G31,'Kraken Trades'!$A$2:$A$28,'Kraken Trades'!$A$2:$A$28,"--",0) -> -- | Q31: =_xlfn.XLOOKUP(G31,'Kraken Trades'!$A$2:$A$28,'Kraken Trades'!$B$2:$B$28,"--",0) -> -- | R31: =_xlfn.XLOOKUP(G31,'Kraken Trades'!$A$2:$A$28,'Kraken Trades'!$C$2:$C$28,"--",0) -> -- | S31: =_xlfn.XLOOKUP(G31,'Kraken Trades'!$A$2:$A$28,'Kraken Trades'!$D$2:$D$28,"--",0) -> -- | T31: =_xlfn.XLOOKUP(G31,'Kraken Trades'!$A$2:$A$28,'Kraken Trades'!$E$2:$E$28,"--",0) -> -- | U31: =_xlfn.XLOOKUP(G31,'Kraken Trades'!$A$2:$A$28,'Kraken Trades'!$F$2:$F$28,"--",0) -> -- | V31: =_xlfn.XLOOKUP(G31,'Kraken Trades'!$A$2:$A$28,'Kraken Trades'!$G$2:$G$28,"--",0) -> -- | W31: =_xlfn.XLOOKUP(G31,'Kraken Trades'!$A$2:$A$28,'Kraken Trades'!$H$2:$H$28,"--",0) -> -- | X31: =_xlfn.XLOOKUP(G31,'Kraken Trades'!$A$2:$A$28,'Kraken Trades'!$I$2:$I$28,"--",0) -> -- | Y31: =_xlfn.XLOOKUP(G31,'Kraken Trades'!$A$2:$A$28,'Kraken Trades'!$J$2:$J$28,"--",0) -> -- | Z31: =_xlfn.XLOOKUP(G31,'Kraken Trades'!$A$2:$A$28,'Kraken Trades'!$K$2:$K$28,"--",0) -> -- | AA31: =_xlfn.XLOOKUP(G31,'Kraken Trades'!$A$2:$A$28,'Kraken Trades'!$L$2:$L$28,"--",0) -> -- | AB31: =_xlfn.XLOOKUP(G31,'Kraken Trades'!$A$2:$A$28,'Kraken Trades'!$M$2:$M$28,"--",0) -> --
B32: yes | E32: =_xlfn.XLOOKUP(D32,'DEST TAGs'!$A$2:$A$5,'DEST TAGs'!$B$2:$B$5,"--",0) -> -- | F32: LPQTWZ-2JQVI-SCLWMP | G32: AIBFEVW-VQSPR2-XZQSSP | H32: 44954.506 | I32: withdrawal | K32: currency | L32: XXRP | M32: -530 | N32: 0.02 | O32: 0.90944334 | P32: =_xlfn.XLOOKUP(G32,'Kraken Trades'!$A$2:$A$28,'Kraken Trades'!$A$2:$A$28,"--",0) -> -- | Q32: =_xlfn.XLOOKUP(G32,'Kraken Trades'!$A$2:$A$28,'Kraken Trades'!$B$2:$B$28,"--",0) -> -- | R32: =_xlfn.XLOOKUP(G32,'Kraken Trades'!$A$2:$A$28,'Kraken Trades'!$C$2:$C$28,"--",0) -> -- | S32: =_xlfn.XLOOKUP(G32,'Kraken Trades'!$A$2:$A$28,'Kraken Trades'!$D$2:$D$28,"--",0) -> -- | T32: =_xlfn.XLOOKUP(G32,'Kraken Trades'!$A$2:$A$28,'Kraken Trades'!$E$2:$E$28,"--",0) -> -- | U32: =_xlfn.XLOOKUP(G32,'Kraken Trades'!$A$2:$A$28,'Kraken Trades'!$F$2:$F$28,"--",0) -> -- | V32: =_xlfn.XLOOKUP(G32,'Kraken Trades'!$A$2:$A$28,'Kraken Trades'!$G$2:$G$28,"--",0) -> -- | W32: =_xlfn.XLOOKUP(G32,'Kraken Trades'!$A$2:$A$28,'Kraken Trades'!$H$2:$H$28,"--",0) -> -- | X32: =_xlfn.XLOOKUP(G32,'Kraken Trades'!$A$2:$A$28,'Kraken Trades'!$I$2:$I$28,"--",0) -> -- | Y32: =_xlfn.XLOOKUP(G32,'Kraken Trades'!$A$2:$A$28,'Kraken Trades'!$J$2:$J$28,"--",0) -> -- | Z32: =_xlfn.XLOOKUP(G32,'Kraken Trades'!$A$2:$A$28,'Kraken Trades'!$K$2:$K$28,"--",0) -> -- | AA32: =_xlfn.XLOOKUP(G32,'Kraken Trades'!$A$2:$A$28,'Kraken Trades'!$L$2:$L$28,"--",0) -> -- | AB32: =_xlfn.XLOOKUP(G32,'Kraken Trades'!$A$2:$A$28,'Kraken Trades'!$M$2:$M$28,"--",0) -> --
B33: yes | E33: =_xlfn.XLOOKUP(D33,'DEST TAGs'!$A$2:$A$5,'DEST TAGs'!$B$2:$B$5,"--",0) -> -- | G33: QYPBDDK-QJQ5AO-UIAHOE | H33: 44971.647 | I33: deposit | K33: currency | L33: ZGBP | M33: 675 | N33: 0 | P33: =_xlfn.XLOOKUP(G33,'Kraken Trades'!$A$2:$A$28,'Kraken Trades'!$A$2:$A$28,"--",0) -> -- | Q33: =_xlfn.XLOOKUP(G33,'Kraken Trades'!$A$2:$A$28,'Kraken Trades'!$B$2:$B$28,"--",0) -> -- | R33: =_xlfn.XLOOKUP(G33,'Kraken Trades'!$A$2:$A$28,'Kraken Trades'!$C$2:$C$28,"--",0) -> -- | S33: =_xlfn.XLOOKUP(G33,'Kraken Trades'!$A$2:$A$28,'Kraken Trades'!$D$2:$D$28,"--",0) -> -- | T33: =_xlfn.XLOOKUP(G33,'Kraken Trades'!$A$2:$A$28,'Kraken Trades'!$E$2:$E$28,"--",0) -> -- | U33: =_xlfn.XLOOKUP(G33,'Kraken Trades'!$A$2:$A$28,'Kraken Trades'!$F$2:$F$28,"--",0) -> -- | V33: =_xlfn.XLOOKUP(G33,'Kraken Trades'!$A$2:$A$28,'Kraken Trades'!$G$2:$G$28,"--",0) -> -- | W33: =_xlfn.XLOOKUP(G33,'Kraken Trades'!$A$2:$A$28,'Kraken Trades'!$H$2:$H$28,"--",0) -> -- | X33: =_xlfn.XLOOKUP(G33,'Kraken Trades'!$A$2:$A$28,'Kraken Trades'!$I$2:$I$28,"--",0) -> -- | Y33: =_xlfn.XLOOKUP(G33,'Kraken Trades'!$A$2:$A$28,'Kraken Trades'!$J$2:$J$28,"--",0) -> -- | Z33: =_xlfn.XLOOKUP(G33,'Kraken Trades'!$A$2:$A$28,'Kraken Trades'!$K$2:$K$28,"--",0) -> -- | AA33: =_xlfn.XLOOKUP(G33,'Kraken Trades'!$A$2:$A$28,'Kraken Trades'!$L$2:$L$28,"--",0) -> -- | AB33: =_xlfn.XLOOKUP(G33,'Kraken Trades'!$A$2:$A$28,'Kraken Trades'!$M$2:$M$28,"--",0) -> --
B34: yes | E34: =_xlfn.XLOOKUP(D34,'DEST TAGs'!$A$2:$A$5,'DEST TAGs'!$B$2:$B$5,"--",0) -> -- | F34: LJDRTG-VVQ57-QCRY3G | G34: QYPBDDK-QJQ5AO-UIAHOE | H34: 44971.688 | I34: deposit | K34: currency | L34: ZGBP | M34: 675 | N34: 0 | O34: 676.0379 | P34: =_xlfn.XLOOKUP(G34,'Kraken Trades'!$A$2:$A$28,'Kraken Trades'!$A$2:$A$28,"--",0) -> -- | Q34: =_xlfn.XLOOKUP(G34,'Kraken Trades'!$A$2:$A$28,'Kraken Trades'!$B$2:$B$28,"--",0) -> -- | R34: =_xlfn.XLOOKUP(G34,'Kraken Trades'!$A$2:$A$28,'Kraken Trades'!$C$2:$C$28,"--",0) -> -- | S34: =_xlfn.XLOOKUP(G34,'Kraken Trades'!$A$2:$A$28,'Kraken Trades'!$D$2:$D$28,"--",0) -> -- | T34: =_xlfn.XLOOKUP(G34,'Kraken Trades'!$A$2:$A$28,'Kraken Trades'!$E$2:$E$28,"--",0) -> -- | U34: =_xlfn.XLOOKUP(G34,'Kraken Trades'!$A$2:$A$28,'Kraken Trades'!$F$2:$F$28,"--",0) -> -- | V34: =_xlfn.XLOOKUP(G34,'Kraken Trades'!$A$2:$A$28,'Kraken Trades'!$G$2:$G$28,"--",0) -> -- | W34: =_xlfn.XLOOKUP(G34,'Kraken Trades'!$A$2:$A$28,'Kraken Trades'!$H$2:$H$28,"--",0) -> -- | X34: =_xlfn.XLOOKUP(G34,'Kraken Trades'!$A$2:$A$28,'Kraken Trades'!$I$2:$I$28,"--",0) -> -- | Y34: =_xlfn.XLOOKUP(G34,'Kraken Trades'!$A$2:$A$28,'Kraken Trades'!$J$2:$J$28,"--",0) -> -- | Z34: =_xlfn.XLOOKUP(G34,'Kraken Trades'!$A$2:$A$28,'Kraken Trades'!$K$2:$K$28,"--",0) -> -- | AA34: =_xlfn.XLOOKUP(G34,'Kraken Trades'!$A$2:$A$28,'Kraken Trades'!$L$2:$L$28,"--",0) -> -- | AB34: =_xlfn.XLOOKUP(G34,'Kraken Trades'!$A$2:$A$28,'Kraken Trades'!$M$2:$M$28,"--",0) -> --
